<?xml version="1.0"?>
<sdf version="1.4">
  <model name="caroca">
    <!--Definition of the robot frame-->
    <link name="frame">
      <pose>0 0 0 0 0 0</pose>
      <inertial>
        <inertia>
          <ixx>100000</ixx>
          <iyy>100000</iyy>
          <izz>100000</izz>
          <ixy>0</ixy>
          <ixz>0</ixz>
          <iyz>0</iyz>
        </inertia>
        <mass>100000</mass>
      </inertial>
      <visual name="visual1">
        <geometry>
          <cylinder>
            <radius>0.02</radius>
            <length>3.5</length>
          </cylinder>
        </geometry>
        <pose>-3.500000 -2.000000 1.750000 0.000000 0.000000 0.000000</pose>
        <material>
          <script>
            <uri>file://media/materials/scripts/kitchen.material</uri>
            <name>Gazebo/Grey</name>
          </script>
        </material>
      </visual>
      <collision name="collision1">
        <geometry>
          <cylinder>
            <radius>0.02</radius>
          </cylinder>
        </geometry>
        <pose>-3.500000 -2.000000 1.750000 0.000000 0.000000 0.000000</pose>
      </collision>
      <visual name="visual2">
        <geometry>
          <cylinder>
            <radius>0.02</radius>
            <length>4.0</length>
          </cylinder>
        </geometry>
        <pose>-3.500000 0.000000 0.000000 1.570796 0.000000 0.000000</pose>
        <material>
          <script>
            <uri>file://media/materials/scripts/kitchen.material</uri>
            <name>Gazebo/Grey</name>
          </script>
        </material>
      </visual>
      <collision name="collision2">
        <geometry>
          <cylinder>
            <radius>0.02</radius>
          </cylinder>
        </geometry>
        <pose>-3.500000 0.000000 0.000000 1.570796 0.000000 0.000000</pose>
      </collision>
      <visual name="visual3">
        <geometry>
          <cylinder>
            <radius>0.02</radius>
            <length>7.0</length>
          </cylinder>
        </geometry>
        <pose>0.000000 -2.000000 0.000000 0.000000 1.570796 0.000000</pose>
        <material>
          <script>
            <uri>file://media/materials/scripts/kitchen.material</uri>
            <name>Gazebo/Grey</name>
          </script>
        </material>
      </visual>
      <collision name="collision3">
        <geometry>
          <cylinder>
            <radius>0.02</radius>
          </cylinder>
        </geometry>
        <pose>0.000000 -2.000000 0.000000 0.000000 1.570796 0.000000</pose>
      </collision>
      <visual name="visual4">
        <geometry>
          <cylinder>
            <radius>0.02</radius>
            <length>4.0</length>
          </cylinder>
        </geometry>
        <pose>-3.500000 0.000000 3.500000 1.570796 0.000000 0.000000</pose>
        <material>
          <script>
            <uri>file://media/materials/scripts/kitchen.material</uri>
            <name>Gazebo/Grey</name>
          </script>
        </material>
      </visual>
      <collision name="collision4">
        <geometry>
          <cylinder>
            <radius>0.02</radius>
          </cylinder>
        </geometry>
        <pose>-3.500000 0.000000 3.500000 1.570796 0.000000 0.000000</pose>
      </collision>
      <visual name="visual5">
        <geometry>
          <cylinder>
            <radius>0.02</radius>
            <length>7.0</length>
          </cylinder>
        </geometry>
        <pose>0.000000 -2.000000 3.500000 0.000000 1.570796 0.000000</pose>
        <material>
          <script>
            <uri>file://media/materials/scripts/kitchen.material</uri>
            <name>Gazebo/Grey</name>
          </script>
        </material>
      </visual>
      <collision name="collision5">
        <geometry>
          <cylinder>
            <radius>0.02</radius>
          </cylinder>
        </geometry>
        <pose>0.000000 -2.000000 3.500000 0.000000 1.570796 0.000000</pose>
      </collision>
      <visual name="visual6">
        <geometry>
          <cylinder>
            <radius>0.02</radius>
            <length>3.5</length>
          </cylinder>
        </geometry>
        <pose>-3.500000 2.000000 1.750000 0.000000 0.000000 0.000000</pose>
        <material>
          <script>
            <uri>file://media/materials/scripts/kitchen.material</uri>
            <name>Gazebo/Grey</name>
          </script>
        </material>
      </visual>
      <collision name="collision6">
        <geometry>
          <cylinder>
            <radius>0.02</radius>
          </cylinder>
        </geometry>
        <pose>-3.500000 2.000000 1.750000 0.000000 0.000000 0.000000</pose>
      </collision>
      <visual name="visual7">
        <geometry>
          <cylinder>
            <radius>0.02</radius>
            <length>7.0</length>
          </cylinder>
        </geometry>
        <pose>0.000000 2.000000 0.000000 0.000000 1.570796 0.000000</pose>
        <material>
          <script>
            <uri>file://media/materials/scripts/kitchen.material</uri>
            <name>Gazebo/Grey</name>
          </script>
        </material>
      </visual>
      <collision name="collision7">
        <geometry>
          <cylinder>
            <radius>0.02</radius>
          </cylinder>
        </geometry>
        <pose>0.000000 2.000000 0.000000 0.000000 1.570796 0.000000</pose>
      </collision>
      <visual name="visual8">
        <geometry>
          <cylinder>
            <radius>0.02</radius>
            <length>7.0</length>
          </cylinder>
        </geometry>
        <pose>0.000000 2.000000 3.500000 0.000000 1.570796 0.000000</pose>
        <material>
          <script>
            <uri>file://media/materials/scripts/kitchen.material</uri>
            <name>Gazebo/Grey</name>
          </script>
        </material>
      </visual>
      <collision name="collision8">
        <geometry>
          <cylinder>
            <radius>0.02</radius>
          </cylinder>
        </geometry>
        <pose>0.000000 2.000000 3.500000 0.000000 1.570796 0.000000</pose>
      </collision>
      <visual name="visual9">
        <geometry>
          <cylinder>
            <radius>0.02</radius>
            <length>3.5</length>
          </cylinder>
        </geometry>
        <pose>3.500000 -2.000000 1.750000 0.000000 0.000000 0.000000</pose>
        <material>
          <script>
            <uri>file://media/materials/scripts/kitchen.material</uri>
            <name>Gazebo/Grey</name>
          </script>
        </material>
      </visual>
      <collision name="collision9">
        <geometry>
          <cylinder>
            <radius>0.02</radius>
          </cylinder>
        </geometry>
        <pose>3.500000 -2.000000 1.750000 0.000000 0.000000 0.000000</pose>
      </collision>
      <visual name="visual10">
        <geometry>
          <cylinder>
            <radius>0.02</radius>
            <length>4.0</length>
          </cylinder>
        </geometry>
        <pose>3.500000 0.000000 0.000000 1.570796 0.000000 0.000000</pose>
        <material>
          <script>
            <uri>file://media/materials/scripts/kitchen.material</uri>
            <name>Gazebo/Grey</name>
          </script>
        </material>
      </visual>
      <collision name="collision10">
        <geometry>
          <cylinder>
            <radius>0.02</radius>
          </cylinder>
        </geometry>
        <pose>3.500000 0.000000 0.000000 1.570796 0.000000 0.000000</pose>
      </collision>
      <visual name="visual11">
        <geometry>
          <cylinder>
            <radius>0.02</radius>
            <length>4.0</length>
          </cylinder>
        </geometry>
        <pose>3.500000 0.000000 3.500000 1.570796 0.000000 0.000000</pose>
        <material>
          <script>
            <uri>file://media/materials/scripts/kitchen.material</uri>
            <name>Gazebo/Grey</name>
          </script>
        </material>
      </visual>
      <collision name="collision11">
        <geometry>
          <cylinder>
            <radius>0.02</radius>
          </cylinder>
        </geometry>
        <pose>3.500000 0.000000 3.500000 1.570796 0.000000 0.000000</pose>
      </collision>
      <visual name="visual12">
        <geometry>
          <cylinder>
            <radius>0.02</radius>
            <length>3.5</length>
          </cylinder>
        </geometry>
        <pose>3.500000 2.000000 1.750000 0.000000 0.000000 0.000000</pose>
        <material>
          <script>
            <uri>file://media/materials/scripts/kitchen.material</uri>
            <name>Gazebo/Grey</name>
          </script>
        </material>
      </visual>
      <collision name="collision12">
        <geometry>
          <cylinder>
            <radius>0.02</radius>
          </cylinder>
        </geometry>
        <pose>3.500000 2.000000 1.750000 0.000000 0.000000 0.000000</pose>
      </collision>
    </link>
    <!--Definition of the robot cables-->
    <!--Definition of the robot platform-->
    <link name="platform">
      <pose>0.000000 0.000000 0.200000 0.000000 0.000000 0.000000</pose>
      <visual name="visualpf">
        <geometry>
          <box>
            <size>1.200000 0.600000 0.400000</size>
          </box>
        </geometry>
        <material>
          <script>
            <uri>file://media/materials/scripts/kitchen.material</uri>
            <name>Gazebo/Blue</name>
          </script>
        </material>
      </visual>
      <collision name="collisionpf">
        <geometry>
          <box>
            <size>1.200000 0.600000 0.400000</size>
          </box>
        </geometry>
      </collision>
      <inertial>
        <inertia>
          <ixx>100.0</ixx>
          <iyy>100.0</iyy>
          <izz>100.0</izz>
          <ixy>0.0</ixy>
          <ixz>0.0</ixz>
          <iyz>0.0</iyz>
        </inertia>
        <mass>150</mass>
      </inertial>
    </link>
    <link name="cable0">
      <pose>-2.587628 -1.621700 2.721146 -2.689439 0.811545 -2.158486</pose>
      <visual name="visual">
        <geometry>
          <cylinder>
            <radius>0.005</radius>
            <length>8.78919791562</length>
          </cylinder>
        </geometry>
        <material>
          <script>
            <uri>file://media/materials/scripts/kitchen.material</uri>
            <name>Gazebo/Black</name>
          </script>
        </material>
      </visual>
      <inertial>
        <inertia>
          <ixx>0.001</ixx>
          <iyy>0.001</iyy>
          <izz>0.001</izz>
          <ixy>0</ixy>
          <ixz>0</ixz>
          <iyz>0</iyz>
        </inertia>
        <mass>0.001</mass>
      </inertial>
    </link>
    <link name="virt_X0">
      <inertial>
        <inertia>
          <ixx>0.001</ixx>
          <iyy>0.001</iyy>
          <izz>0.001</izz>
          <ixy>0</ixy>
          <ixz>0</ixz>
          <iyz>0</iyz>
        </inertia>
        <mass>0.001</mass>
      </inertial>
      <pose>-3.500000 -2.000000 3.500000 -2.689439 0.811545 -2.158486</pose>
    </link>
    <joint name="rev_X0" type="revolute">
      <pose>0 0 0 -2.689439 0.811545 -2.158486</pose>
      <parent>frame</parent>
      <child>virt_X0</child>
      <axis>
        <xyz>-0.381665 -0.572885 -0.725351</xyz>
        <limit>
          <effort>100</effort>
          <velocity>10</velocity>
        </limit>
        <dynamics>
          <damping>0.01</damping>
        </dynamics>
      </axis>
    </joint>
    <link name="virt_Y0">
      <inertial>
        <inertia>
          <ixx>0.001</ixx>
          <iyy>0.001</iyy>
          <izz>0.001</izz>
          <ixy>0</ixy>
          <ixz>0</ixz>
          <iyz>0</iyz>
        </inertia>
        <mass>0.001</mass>
      </inertial>
      <pose>-3.500000 -2.000000 3.500000 -2.689439 0.811545 -2.158486</pose>
    </link>
    <joint name="rev_Y0" type="revolute">
      <pose>0 0 0 -2.689439 0.811545 -2.158486</pose>
      <parent>virt_X0</parent>
      <child>virt_Y0</child>
      <axis>
        <xyz>-0.572885 0.762462 -0.300755</xyz>
        <limit>
          <effort>100</effort>
          <velocity>10</velocity>
        </limit>
        <dynamics>
          <damping>0.01</damping>
        </dynamics>
      </axis>
    </joint>
    <joint name="cable0" type="prismatic">
      <pose>0 0 -0.977929 -2.689439 0.811545 -2.158486</pose>
      <parent>virt_Y0</parent>
      <child>cable0</child>
      <axis>
        <xyz>-0.725351 -0.300755 0.619202</xyz>
        <limit>
          <lower>-4.39459895781</lower>
          <upper>4.39459895781</upper>
          <effort>10000</effort>
          <velocity>10</velocity>
        </limit>
        <dynamics>
          <damping>1</damping>
        </dynamics>
      </axis>
    </joint>
    <link name="virt_Xpf0">
      <inertial>
        <inertia>
          <ixx>0.001</ixx>
          <iyy>0.001</iyy>
          <izz>0.001</izz>
          <ixy>0</ixy>
          <ixz>0</ixz>
          <iyz>0</iyz>
        </inertia>
        <mass>0.001</mass>
      </inertial>
      <pose>0.600000 -0.300000 0.000000 -2.689439 0.811545 -2.158486</pose>
    </link>
    <joint name="rev_Xpf0" type="revolute">
      <pose>0 0 0 -2.689439 0.811545 -2.158486</pose>
      <parent>platform</parent>
      <child>virt_Xpf0</child>
      <axis>
        <xyz>1 0 0</xyz>
        <limit>
          <effort>100</effort>
          <velocity>10</velocity>
        </limit>
        <dynamics>
          <damping>0.01</damping>
        </dynamics>
      </axis>
    </joint>
    <link name="virt_Ypf0">
      <inertial>
        <inertia>
          <ixx>0.001</ixx>
          <iyy>0.001</iyy>
          <izz>0.001</izz>
          <ixy>0</ixy>
          <ixz>0</ixz>
          <iyz>0</iyz>
        </inertia>
        <mass>0.001</mass>
      </inertial>
      <pose>0.600000 -0.300000 0.000000 -2.689439 0.811545 -2.158486</pose>
    </link>
    <joint name="rev_Ypf0" type="revolute">
      <pose>0 0 0 -2.689439 0.811545 -2.158486</pose>
      <parent>virt_Xpf0</parent>
      <child>virt_Ypf0</child>
      <axis>
        <xyz>0 1 0</xyz>
        <limit>
          <effort>100</effort>
          <velocity>10</velocity>
        </limit>
        <dynamics>
          <damping>0.01</damping>
        </dynamics>
      </axis>
    </joint>
    <joint name="rev_Zpf0" type="revolute">
      <pose>0 0 0 -2.689439 0.811545 -2.158486</pose>
      <child>virt_Ypf0</child>
      <parent>cable0</parent>
      <axis>
        <xyz>0 0 1</xyz>
        <limit>
          <effort>100</effort>
          <velocity>10</velocity>
        </limit>
        <dynamics>
          <damping>0.01</damping>
        </dynamics>
      </axis>
    </joint>
    <link name="cable1">
      <pose>-3.239649 -1.793514 3.221693 -2.503273 0.644323 -1.580831</pose>
      <visual name="visual">
        <geometry>
          <cylinder>
            <radius>0.005</radius>
            <length>8.78919791562</length>
          </cylinder>
        </geometry>
        <material>
          <script>
            <uri>file://media/materials/scripts/kitchen.material</uri>
            <name>Gazebo/Black</name>
          </script>
        </material>
      </visual>
      <inertial>
        <inertia>
          <ixx>0.001</ixx>
          <iyy>0.001</iyy>
          <izz>0.001</izz>
          <ixy>0</ixy>
          <ixz>0</ixz>
          <iyz>0</iyz>
        </inertia>
        <mass>0.001</mass>
      </inertial>
    </link>
    <link name="virt_X1">
      <inertial>
        <inertia>
          <ixx>0.001</ixx>
          <iyy>0.001</iyy>
          <izz>0.001</izz>
          <ixy>0</ixy>
          <ixz>0</ixz>
          <iyz>0</iyz>
        </inertia>
        <mass>0.001</mass>
      </inertial>
      <pose>-3.500000 -2.000000 3.500000 -2.503273 0.644323 -1.580831</pose>
    </link>
    <joint name="rev_X1" type="revolute">
      <pose>0 0 0 -2.503273 0.644323 -1.580831</pose>
      <parent>frame</parent>
      <child>virt_X1</child>
      <axis>
        <xyz>-0.008023 -0.799466 -0.600657</xyz>
        <limit>
          <effort>100</effort>
          <velocity>10</velocity>
        </limit>
        <dynamics>
          <damping>0.01</damping>
        </dynamics>
      </axis>
    </joint>
    <link name="virt_Y1">
      <inertial>
        <inertia>
          <ixx>0.001</ixx>
          <iyy>0.001</iyy>
          <izz>0.001</izz>
          <ixy>0</ixy>
          <ixz>0</ixz>
          <iyz>0</iyz>
        </inertia>
        <mass>0.001</mass>
      </inertial>
      <pose>-3.500000 -2.000000 3.500000 -2.503273 0.644323 -1.580831</pose>
    </link>
    <joint name="rev_Y1" type="revolute">
      <pose>0 0 0 -2.503273 0.644323 -1.580831</pose>
      <parent>virt_X1</parent>
      <child>virt_Y1</child>
      <axis>
        <xyz>-0.799466 0.365941 -0.476383</xyz>
        <limit>
          <effort>100</effort>
          <velocity>10</velocity>
        </limit>
        <dynamics>
          <damping>0.01</damping>
        </dynamics>
      </axis>
    </joint>
    <joint name="cable1" type="prismatic">
      <pose>0 0 -0.394531 -2.503273 0.644323 -1.580831</pose>
      <parent>virt_Y1</parent>
      <child>cable1</child>
      <axis>
        <xyz>-0.600657 -0.476383 0.642082</xyz>
        <limit>
          <lower>-4.39459895781</lower>
          <upper>4.39459895781</upper>
          <effort>10000</effort>
          <velocity>10</velocity>
        </limit>
        <dynamics>
          <damping>1</damping>
        </dynamics>
      </axis>
    </joint>
    <link name="virt_Xpf1">
      <inertial>
        <inertia>
          <ixx>0.001</ixx>
          <iyy>0.001</iyy>
          <izz>0.001</izz>
          <ixy>0</ixy>
          <ixz>0</ixz>
          <iyz>0</iyz>
        </inertia>
        <mass>0.001</mass>
      </inertial>
      <pose>-0.600000 0.300000 0.400000 -2.503273 0.644323 -1.580831</pose>
    </link>
    <joint name="rev_Xpf1" type="revolute">
      <pose>0 0 0 -2.503273 0.644323 -1.580831</pose>
      <parent>platform</parent>
      <child>virt_Xpf1</child>
      <axis>
        <xyz>1 0 0</xyz>
        <limit>
          <effort>100</effort>
          <velocity>10</velocity>
        </limit>
        <dynamics>
          <damping>0.01</damping>
        </dynamics>
      </axis>
    </joint>
    <link name="virt_Ypf1">
      <inertial>
        <inertia>
          <ixx>0.001</ixx>
          <iyy>0.001</iyy>
          <izz>0.001</izz>
          <ixy>0</ixy>
          <ixz>0</ixz>
          <iyz>0</iyz>
        </inertia>
        <mass>0.001</mass>
      </inertial>
      <pose>-0.600000 0.300000 0.400000 -2.503273 0.644323 -1.580831</pose>
    </link>
    <joint name="rev_Ypf1" type="revolute">
      <pose>0 0 0 -2.503273 0.644323 -1.580831</pose>
      <parent>virt_Xpf1</parent>
      <child>virt_Ypf1</child>
      <axis>
        <xyz>0 1 0</xyz>
        <limit>
          <effort>100</effort>
          <velocity>10</velocity>
        </limit>
        <dynamics>
          <damping>0.01</damping>
        </dynamics>
      </axis>
    </joint>
    <joint name="rev_Zpf1" type="revolute">
      <pose>0 0 0 -2.503273 0.644323 -1.580831</pose>
      <child>virt_Ypf1</child>
      <parent>cable1</parent>
      <axis>
        <xyz>0 0 1</xyz>
        <limit>
          <effort>100</effort>
          <velocity>10</velocity>
        </limit>
        <dynamics>
          <damping>0.01</damping>
        </dynamics>
      </axis>
    </joint>
    <link name="cable2">
      <pose>2.728091 -1.679940 2.916362 -2.639989 -0.859190 2.121803</pose>
      <visual name="visual">
        <geometry>
          <cylinder>
            <radius>0.005</radius>
            <length>8.78919791562</length>
          </cylinder>
        </geometry>
        <material>
          <script>
            <uri>file://media/materials/scripts/kitchen.material</uri>
            <name>Gazebo/Black</name>
          </script>
        </material>
      </visual>
      <inertial>
        <inertia>
          <ixx>0.001</ixx>
          <iyy>0.001</iyy>
          <izz>0.001</izz>
          <ixy>0</ixy>
          <ixz>0</ixz>
          <iyz>0</iyz>
        </inertia>
        <mass>0.001</mass>
      </inertial>
    </link>
    <link name="virt_X2">
      <inertial>
        <inertia>
          <ixx>0.001</ixx>
          <iyy>0.001</iyy>
          <izz>0.001</izz>
          <ixy>0</ixy>
          <ixz>0</ixz>
          <iyz>0</iyz>
        </inertia>
        <mass>0.001</mass>
      </inertial>
      <pose>3.500000 -2.000000 3.500000 -2.639989 -0.859190 2.121803</pose>
    </link>
    <joint name="rev_X2" type="revolute">
      <pose>0 0 0 -2.639989 -0.859190 2.121803</pose>
      <parent>frame</parent>
      <child>virt_X2</child>
      <axis>
        <xyz>-0.341902 0.556398 0.757314</xyz>
        <limit>
          <effort>100</effort>
          <velocity>10</velocity>
        </limit>
        <dynamics>
          <damping>0.01</damping>
        </dynamics>
      </axis>
    </joint>
    <link name="virt_Y2">
      <inertial>
        <inertia>
          <ixx>0.001</ixx>
          <iyy>0.001</iyy>
          <izz>0.001</izz>
          <ixy>0</ixy>
          <ixz>0</ixz>
          <iyz>0</iyz>
        </inertia>
        <mass>0.001</mass>
      </inertial>
      <pose>3.500000 -2.000000 3.500000 -2.639989 -0.859190 2.121803</pose>
    </link>
    <joint name="rev_Y2" type="revolute">
      <pose>0 0 0 -2.639989 -0.859190 2.121803</pose>
      <parent>virt_X2</parent>
      <child>virt_Y2</child>
      <axis>
        <xyz>0.556398 0.769298 -0.314008</xyz>
        <limit>
          <effort>100</effort>
          <velocity>10</velocity>
        </limit>
        <dynamics>
          <damping>0.01</damping>
        </dynamics>
      </axis>
    </joint>
    <joint name="cable2" type="prismatic">
      <pose>0 0 -0.827373 -2.639989 -0.859190 2.121803</pose>
      <parent>virt_Y2</parent>
      <child>cable2</child>
      <axis>
        <xyz>0.757314 -0.314008 0.572603</xyz>
        <limit>
          <lower>-4.39459895781</lower>
          <upper>4.39459895781</upper>
          <effort>10000</effort>
          <velocity>10</velocity>
        </limit>
        <dynamics>
          <damping>1</damping>
        </dynamics>
      </axis>
    </joint>
    <link name="virt_Xpf2">
      <inertial>
        <inertia>
          <ixx>0.001</ixx>
          <iyy>0.001</iyy>
          <izz>0.001</izz>
          <ixy>0</ixy>
          <ixz>0</ixz>
          <iyz>0</iyz>
        </inertia>
        <mass>0.001</mass>
      </inertial>
      <pose>-0.600000 -0.300000 0.400000 -2.639989 -0.859190 2.121803</pose>
    </link>
    <joint name="rev_Xpf2" type="revolute">
      <pose>0 0 0 -2.639989 -0.859190 2.121803</pose>
      <parent>platform</parent>
      <child>virt_Xpf2</child>
      <axis>
        <xyz>1 0 0</xyz>
        <limit>
          <effort>100</effort>
          <velocity>10</velocity>
        </limit>
        <dynamics>
          <damping>0.01</damping>
        </dynamics>
      </axis>
    </joint>
    <link name="virt_Ypf2">
      <inertial>
        <inertia>
          <ixx>0.001</ixx>
          <iyy>0.001</iyy>
          <izz>0.001</izz>
          <ixy>0</ixy>
          <ixz>0</ixz>
          <iyz>0</iyz>
        </inertia>
        <mass>0.001</mass>
      </inertial>
      <pose>-0.600000 -0.300000 0.400000 -2.639989 -0.859190 2.121803</pose>
    </link>
    <joint name="rev_Ypf2" type="revolute">
      <pose>0 0 0 -2.639989 -0.859190 2.121803</pose>
      <parent>virt_Xpf2</parent>
      <child>virt_Ypf2</child>
      <axis>
        <xyz>0 1 0</xyz>
        <limit>
          <effort>100</effort>
          <velocity>10</velocity>
        </limit>
        <dynamics>
          <damping>0.01</damping>
        </dynamics>
      </axis>
    </joint>
    <joint name="rev_Zpf2" type="revolute">
      <pose>0 0 0 -2.639989 -0.859190 2.121803</pose>
      <child>virt_Ypf2</child>
      <parent>cable2</parent>
      <axis>
        <xyz>0 0 1</xyz>
        <limit>
          <effort>100</effort>
          <velocity>10</velocity>
        </limit>
        <dynamics>
          <damping>0.01</damping>
        </dynamics>
      </axis>
    </joint>
    <link name="cable3">
      <pose>3.101777 -1.684168 3.019386 -2.560212 -0.605635 1.614157</pose>
      <visual name="visual">
        <geometry>
          <cylinder>
            <radius>0.005</radius>
            <length>8.78919791562</length>
          </cylinder>
        </geometry>
        <material>
          <script>
            <uri>file://media/materials/scripts/kitchen.material</uri>
            <name>Gazebo/Black</name>
          </script>
        </material>
      </visual>
      <inertial>
        <inertia>
          <ixx>0.001</ixx>
          <iyy>0.001</iyy>
          <izz>0.001</izz>
          <ixy>0</ixy>
          <ixz>0</ixz>
          <iyz>0</iyz>
        </inertia>
        <mass>0.001</mass>
      </inertial>
    </link>
    <link name="virt_X3">
      <inertial>
        <inertia>
          <ixx>0.001</ixx>
          <iyy>0.001</iyy>
          <izz>0.001</izz>
          <ixy>0</ixy>
          <ixz>0</ixz>
          <iyz>0</iyz>
        </inertia>
        <mass>0.001</mass>
      </inertial>
      <pose>3.500000 -2.000000 3.500000 -2.560212 -0.605635 1.614157</pose>
    </link>
    <joint name="rev_X3" type="revolute">
      <pose>0 0 0 -2.560212 -0.605635 1.614157</pose>
      <parent>frame</parent>
      <child>virt_X3</child>
      <axis>
        <xyz>-0.035638 0.821368 0.569284</xyz>
        <limit>
          <effort>100</effort>
          <velocity>10</velocity>
        </limit>
        <dynamics>
          <damping>0.01</damping>
        </dynamics>
      </axis>
    </joint>
    <link name="virt_Y3">
      <inertial>
        <inertia>
          <ixx>0.001</ixx>
          <iyy>0.001</iyy>
          <izz>0.001</izz>
          <ixy>0</ixy>
          <ixz>0</ixz>
          <iyz>0</iyz>
        </inertia>
        <mass>0.001</mass>
      </inertial>
      <pose>3.500000 -2.000000 3.500000 -2.560212 -0.605635 1.614157</pose>
    </link>
    <joint name="rev_Y3" type="revolute">
      <pose>0 0 0 -2.560212 -0.605635 1.614157</pose>
      <parent>virt_X3</parent>
      <child>virt_Y3</child>
      <axis>
        <xyz>0.821368 0.348570 -0.451501</xyz>
        <limit>
          <effort>100</effort>
          <velocity>10</velocity>
        </limit>
        <dynamics>
          <damping>0.01</damping>
        </dynamics>
      </axis>
    </joint>
    <joint name="cable3" type="prismatic">
      <pose>0 0 -0.603459 -2.560212 -0.605635 1.614157</pose>
      <parent>virt_Y3</parent>
      <child>cable3</child>
      <axis>
        <xyz>0.569284 -0.451501 0.687067</xyz>
        <limit>
          <lower>-4.39459895781</lower>
          <upper>4.39459895781</upper>
          <effort>10000</effort>
          <velocity>10</velocity>
        </limit>
        <dynamics>
          <damping>1</damping>
        </dynamics>
      </axis>
    </joint>
    <link name="virt_Xpf3">
      <inertial>
        <inertia>
          <ixx>0.001</ixx>
          <iyy>0.001</iyy>
          <izz>0.001</izz>
          <ixy>0</ixy>
          <ixz>0</ixz>
          <iyz>0</iyz>
        </inertia>
        <mass>0.001</mass>
      </inertial>
      <pose>0.600000 0.300000 0.000000 -2.560212 -0.605635 1.614157</pose>
    </link>
    <joint name="rev_Xpf3" type="revolute">
      <pose>0 0 0 -2.560212 -0.605635 1.614157</pose>
      <parent>platform</parent>
      <child>virt_Xpf3</child>
      <axis>
        <xyz>1 0 0</xyz>
        <limit>
          <effort>100</effort>
          <velocity>10</velocity>
        </limit>
        <dynamics>
          <damping>0.01</damping>
        </dynamics>
      </axis>
    </joint>
    <link name="virt_Ypf3">
      <inertial>
        <inertia>
          <ixx>0.001</ixx>
          <iyy>0.001</iyy>
          <izz>0.001</izz>
          <ixy>0</ixy>
          <ixz>0</ixz>
          <iyz>0</iyz>
        </inertia>
        <mass>0.001</mass>
      </inertial>
      <pose>0.600000 0.300000 0.000000 -2.560212 -0.605635 1.614157</pose>
    </link>
    <joint name="rev_Ypf3" type="revolute">
      <pose>0 0 0 -2.560212 -0.605635 1.614157</pose>
      <parent>virt_Xpf3</parent>
      <child>virt_Ypf3</child>
      <axis>
        <xyz>0 1 0</xyz>
        <limit>
          <effort>100</effort>
          <velocity>10</velocity>
        </limit>
        <dynamics>
          <damping>0.01</damping>
        </dynamics>
      </axis>
    </joint>
    <joint name="rev_Zpf3" type="revolute">
      <pose>0 0 0 -2.560212 -0.605635 1.614157</pose>
      <child>virt_Ypf3</child>
      <parent>cable3</parent>
      <axis>
        <xyz>0 0 1</xyz>
        <limit>
          <effort>100</effort>
          <velocity>10</velocity>
        </limit>
        <dynamics>
          <damping>0.01</damping>
        </dynamics>
      </axis>
    </joint>
    <link name="cable4">
      <pose>-3.101777 1.684168 3.019386 2.560212 0.605635 1.614157</pose>
      <visual name="visual">
        <geometry>
          <cylinder>
            <radius>0.005</radius>
            <length>8.78919791562</length>
          </cylinder>
        </geometry>
        <material>
          <script>
            <uri>file://media/materials/scripts/kitchen.material</uri>
            <name>Gazebo/Black</name>
          </script>
        </material>
      </visual>
      <inertial>
        <inertia>
          <ixx>0.001</ixx>
          <iyy>0.001</iyy>
          <izz>0.001</izz>
          <ixy>0</ixy>
          <ixz>0</ixz>
          <iyz>0</iyz>
        </inertia>
        <mass>0.001</mass>
      </inertial>
    </link>
    <link name="virt_X4">
      <inertial>
        <inertia>
          <ixx>0.001</ixx>
          <iyy>0.001</iyy>
          <izz>0.001</izz>
          <ixy>0</ixy>
          <ixz>0</ixz>
          <iyz>0</iyz>
        </inertia>
        <mass>0.001</mass>
      </inertial>
      <pose>-3.500000 2.000000 3.500000 2.560212 0.605635 1.614157</pose>
    </link>
    <joint name="rev_X4" type="revolute">
      <pose>0 0 0 2.560212 0.605635 1.614157</pose>
      <parent>frame</parent>
      <child>virt_X4</child>
      <axis>
        <xyz>-0.035638 0.821368 -0.569284</xyz>
        <limit>
          <effort>100</effort>
          <velocity>10</velocity>
        </limit>
        <dynamics>
          <damping>0.01</damping>
        </dynamics>
      </axis>
    </joint>
    <link name="virt_Y4">
      <inertial>
        <inertia>
          <ixx>0.001</ixx>
          <iyy>0.001</iyy>
          <izz>0.001</izz>
          <ixy>0</ixy>
          <ixz>0</ixz>
          <iyz>0</iyz>
        </inertia>
        <mass>0.001</mass>
      </inertial>
      <pose>-3.500000 2.000000 3.500000 2.560212 0.605635 1.614157</pose>
    </link>
    <joint name="rev_Y4" type="revolute">
      <pose>0 0 0 2.560212 0.605635 1.614157</pose>
      <parent>virt_X4</parent>
      <child>virt_Y4</child>
      <axis>
        <xyz>0.821368 0.348570 0.451501</xyz>
        <limit>
          <effort>100</effort>
          <velocity>10</velocity>
        </limit>
        <dynamics>
          <damping>0.01</damping>
        </dynamics>
      </axis>
    </joint>
    <joint name="cable4" type="prismatic">
      <pose>0 0 -0.603459 2.560212 0.605635 1.614157</pose>
      <parent>virt_Y4</parent>
      <child>cable4</child>
      <axis>
        <xyz>-0.569284 0.451501 0.687067</xyz>
        <limit>
          <lower>-4.39459895781</lower>
          <upper>4.39459895781</upper>
          <effort>10000</effort>
          <velocity>10</velocity>
        </limit>
        <dynamics>
          <damping>1</damping>
        </dynamics>
      </axis>
    </joint>
    <link name="virt_Xpf4">
      <inertial>
        <inertia>
          <ixx>0.001</ixx>
          <iyy>0.001</iyy>
          <izz>0.001</izz>
          <ixy>0</ixy>
          <ixz>0</ixz>
          <iyz>0</iyz>
        </inertia>
        <mass>0.001</mass>
      </inertial>
      <pose>-0.600000 -0.300000 0.000000 2.560212 0.605635 1.614157</pose>
    </link>
    <joint name="rev_Xpf4" type="revolute">
      <pose>0 0 0 2.560212 0.605635 1.614157</pose>
      <parent>platform</parent>
      <child>virt_Xpf4</child>
      <axis>
        <xyz>1 0 0</xyz>
        <limit>
          <effort>100</effort>
          <velocity>10</velocity>
        </limit>
        <dynamics>
          <damping>0.01</damping>
        </dynamics>
      </axis>
    </joint>
    <link name="virt_Ypf4">
      <inertial>
        <inertia>
          <ixx>0.001</ixx>
          <iyy>0.001</iyy>
          <izz>0.001</izz>
          <ixy>0</ixy>
          <ixz>0</ixz>
          <iyz>0</iyz>
        </inertia>
        <mass>0.001</mass>
      </inertial>
      <pose>-0.600000 -0.300000 0.000000 2.560212 0.605635 1.614157</pose>
    </link>
    <joint name="rev_Ypf4" type="revolute">
      <pose>0 0 0 2.560212 0.605635 1.614157</pose>
      <parent>virt_Xpf4</parent>
      <child>virt_Ypf4</child>
      <axis>
        <xyz>0 1 0</xyz>
        <limit>
          <effort>100</effort>
          <velocity>10</velocity>
        </limit>
        <dynamics>
          <damping>0.01</damping>
        </dynamics>
      </axis>
    </joint>
    <joint name="rev_Zpf4" type="revolute">
      <pose>0 0 0 2.560212 0.605635 1.614157</pose>
      <child>virt_Ypf4</child>
      <parent>cable4</parent>
      <axis>
        <xyz>0 0 1</xyz>
        <limit>
          <effort>100</effort>
          <velocity>10</velocity>
        </limit>
        <dynamics>
          <damping>0.01</damping>
        </dynamics>
      </axis>
    </joint>
    <link name="cable5">
      <pose>-2.728091 1.679940 2.916362 2.639989 0.859190 2.121803</pose>
      <visual name="visual">
        <geometry>
          <cylinder>
            <radius>0.005</radius>
            <length>8.78919791562</length>
          </cylinder>
        </geometry>
        <material>
          <script>
            <uri>file://media/materials/scripts/kitchen.material</uri>
            <name>Gazebo/Black</name>
          </script>
        </material>
      </visual>
      <inertial>
        <inertia>
          <ixx>0.001</ixx>
          <iyy>0.001</iyy>
          <izz>0.001</izz>
          <ixy>0</ixy>
          <ixz>0</ixz>
          <iyz>0</iyz>
        </inertia>
        <mass>0.001</mass>
      </inertial>
    </link>
    <link name="virt_X5">
      <inertial>
        <inertia>
          <ixx>0.001</ixx>
          <iyy>0.001</iyy>
          <izz>0.001</izz>
          <ixy>0</ixy>
          <ixz>0</ixz>
          <iyz>0</iyz>
        </inertia>
        <mass>0.001</mass>
      </inertial>
      <pose>-3.500000 2.000000 3.500000 2.639989 0.859190 2.121803</pose>
    </link>
    <joint name="rev_X5" type="revolute">
      <pose>0 0 0 2.639989 0.859190 2.121803</pose>
      <parent>frame</parent>
      <child>virt_X5</child>
      <axis>
        <xyz>-0.341902 0.556398 -0.757314</xyz>
        <limit>
          <effort>100</effort>
          <velocity>10</velocity>
        </limit>
        <dynamics>
          <damping>0.01</damping>
        </dynamics>
      </axis>
    </joint>
    <link name="virt_Y5">
      <inertial>
        <inertia>
          <ixx>0.001</ixx>
          <iyy>0.001</iyy>
          <izz>0.001</izz>
          <ixy>0</ixy>
          <ixz>0</ixz>
          <iyz>0</iyz>
        </inertia>
        <mass>0.001</mass>
      </inertial>
      <pose>-3.500000 2.000000 3.500000 2.639989 0.859190 2.121803</pose>
    </link>
    <joint name="rev_Y5" type="revolute">
      <pose>0 0 0 2.639989 0.859190 2.121803</pose>
      <parent>virt_X5</parent>
      <child>virt_Y5</child>
      <axis>
        <xyz>0.556398 0.769298 0.314008</xyz>
        <limit>
          <effort>100</effort>
          <velocity>10</velocity>
        </limit>
        <dynamics>
          <damping>0.01</damping>
        </dynamics>
      </axis>
    </joint>
    <joint name="cable5" type="prismatic">
      <pose>0 0 -0.827373 2.639989 0.859190 2.121803</pose>
      <parent>virt_Y5</parent>
      <child>cable5</child>
      <axis>
        <xyz>-0.757314 0.314008 0.572603</xyz>
        <limit>
          <lower>-4.39459895781</lower>
          <upper>4.39459895781</upper>
          <effort>10000</effort>
          <velocity>10</velocity>
        </limit>
        <dynamics>
          <damping>1</damping>
        </dynamics>
      </axis>
    </joint>
    <link name="virt_Xpf5">
      <inertial>
        <inertia>
          <ixx>0.001</ixx>
          <iyy>0.001</iyy>
          <izz>0.001</izz>
          <ixy>0</ixy>
          <ixz>0</ixz>
          <iyz>0</iyz>
        </inertia>
        <mass>0.001</mass>
      </inertial>
      <pose>0.600000 0.300000 0.400000 2.639989 0.859190 2.121803</pose>
    </link>
    <joint name="rev_Xpf5" type="revolute">
      <pose>0 0 0 2.639989 0.859190 2.121803</pose>
      <parent>platform</parent>
      <child>virt_Xpf5</child>
      <axis>
        <xyz>1 0 0</xyz>
        <limit>
          <effort>100</effort>
          <velocity>10</velocity>
        </limit>
        <dynamics>
          <damping>0.01</damping>
        </dynamics>
      </axis>
    </joint>
    <link name="virt_Ypf5">
      <inertial>
        <inertia>
          <ixx>0.001</ixx>
          <iyy>0.001</iyy>
          <izz>0.001</izz>
          <ixy>0</ixy>
          <ixz>0</ixz>
          <iyz>0</iyz>
        </inertia>
        <mass>0.001</mass>
      </inertial>
      <pose>0.600000 0.300000 0.400000 2.639989 0.859190 2.121803</pose>
    </link>
    <joint name="rev_Ypf5" type="revolute">
      <pose>0 0 0 2.639989 0.859190 2.121803</pose>
      <parent>virt_Xpf5</parent>
      <child>virt_Ypf5</child>
      <axis>
        <xyz>0 1 0</xyz>
        <limit>
          <effort>100</effort>
          <velocity>10</velocity>
        </limit>
        <dynamics>
          <damping>0.01</damping>
        </dynamics>
      </axis>
    </joint>
    <joint name="rev_Zpf5" type="revolute">
      <pose>0 0 0 2.639989 0.859190 2.121803</pose>
      <child>virt_Ypf5</child>
      <parent>cable5</parent>
      <axis>
        <xyz>0 0 1</xyz>
        <limit>
          <effort>100</effort>
          <velocity>10</velocity>
        </limit>
        <dynamics>
          <damping>0.01</damping>
        </dynamics>
      </axis>
    </joint>
    <link name="cable6">
      <pose>3.239649 1.793514 3.221693 2.503273 -0.644323 -1.580831</pose>
      <visual name="visual">
        <geometry>
          <cylinder>
            <radius>0.005</radius>
            <length>8.78919791562</length>
          </cylinder>
        </geometry>
        <material>
          <script>
            <uri>file://media/materials/scripts/kitchen.material</uri>
            <name>Gazebo/Black</name>
          </script>
        </material>
      </visual>
      <inertial>
        <inertia>
          <ixx>0.001</ixx>
          <iyy>0.001</iyy>
          <izz>0.001</izz>
          <ixy>0</ixy>
          <ixz>0</ixz>
          <iyz>0</iyz>
        </inertia>
        <mass>0.001</mass>
      </inertial>
    </link>
    <link name="virt_X6">
      <inertial>
        <inertia>
          <ixx>0.001</ixx>
          <iyy>0.001</iyy>
          <izz>0.001</izz>
          <ixy>0</ixy>
          <ixz>0</ixz>
          <iyz>0</iyz>
        </inertia>
        <mass>0.001</mass>
      </inertial>
      <pose>3.500000 2.000000 3.500000 2.503273 -0.644323 -1.580831</pose>
    </link>
    <joint name="rev_X6" type="revolute">
      <pose>0 0 0 2.503273 -0.644323 -1.580831</pose>
      <parent>frame</parent>
      <child>virt_X6</child>
      <axis>
        <xyz>-0.008023 -0.799466 0.600657</xyz>
        <limit>
          <effort>100</effort>
          <velocity>10</velocity>
        </limit>
        <dynamics>
          <damping>0.01</damping>
        </dynamics>
      </axis>
    </joint>
    <link name="virt_Y6">
      <inertial>
        <inertia>
          <ixx>0.001</ixx>
          <iyy>0.001</iyy>
          <izz>0.001</izz>
          <ixy>0</ixy>
          <ixz>0</ixz>
          <iyz>0</iyz>
        </inertia>
        <mass>0.001</mass>
      </inertial>
      <pose>3.500000 2.000000 3.500000 2.503273 -0.644323 -1.580831</pose>
    </link>
    <joint name="rev_Y6" type="revolute">
      <pose>0 0 0 2.503273 -0.644323 -1.580831</pose>
      <parent>virt_X6</parent>
      <child>virt_Y6</child>
      <axis>
        <xyz>-0.799466 0.365941 0.476383</xyz>
        <limit>
          <effort>100</effort>
          <velocity>10</velocity>
        </limit>
        <dynamics>
          <damping>0.01</damping>
        </dynamics>
      </axis>
    </joint>
    <joint name="cable6" type="prismatic">
      <pose>0 0 -0.394531 2.503273 -0.644323 -1.580831</pose>
      <parent>virt_Y6</parent>
      <child>cable6</child>
      <axis>
        <xyz>0.600657 0.476383 0.642082</xyz>
        <limit>
          <lower>-4.39459895781</lower>
          <upper>4.39459895781</upper>
          <effort>10000</effort>
          <velocity>10</velocity>
        </limit>
        <dynamics>
          <damping>1</damping>
        </dynamics>
      </axis>
    </joint>
    <link name="virt_Xpf6">
      <inertial>
        <inertia>
          <ixx>0.001</ixx>
          <iyy>0.001</iyy>
          <izz>0.001</izz>
          <ixy>0</ixy>
          <ixz>0</ixz>
          <iyz>0</iyz>
        </inertia>
        <mass>0.001</mass>
      </inertial>
      <pose>0.600000 -0.300000 0.400000 2.503273 -0.644323 -1.580831</pose>
    </link>
    <joint name="rev_Xpf6" type="revolute">
      <pose>0 0 0 2.503273 -0.644323 -1.580831</pose>
      <parent>platform</parent>
      <child>virt_Xpf6</child>
      <axis>
        <xyz>1 0 0</xyz>
        <limit>
          <effort>100</effort>
          <velocity>10</velocity>
        </limit>
        <dynamics>
          <damping>0.01</damping>
        </dynamics>
      </axis>
    </joint>
    <link name="virt_Ypf6">
      <inertial>
        <inertia>
          <ixx>0.001</ixx>
          <iyy>0.001</iyy>
          <izz>0.001</izz>
          <ixy>0</ixy>
          <ixz>0</ixz>
          <iyz>0</iyz>
        </inertia>
        <mass>0.001</mass>
      </inertial>
      <pose>0.600000 -0.300000 0.400000 2.503273 -0.644323 -1.580831</pose>
    </link>
    <joint name="rev_Ypf6" type="revolute">
      <pose>0 0 0 2.503273 -0.644323 -1.580831</pose>
      <parent>virt_Xpf6</parent>
      <child>virt_Ypf6</child>
      <axis>
        <xyz>0 1 0</xyz>
        <limit>
          <effort>100</effort>
          <velocity>10</velocity>
        </limit>
        <dynamics>
          <damping>0.01</damping>
        </dynamics>
      </axis>
    </joint>
    <joint name="rev_Zpf6" type="revolute">
      <pose>0 0 0 2.503273 -0.644323 -1.580831</pose>
      <child>virt_Ypf6</child>
      <parent>cable6</parent>
      <axis>
        <xyz>0 0 1</xyz>
        <limit>
          <effort>100</effort>
          <velocity>10</velocity>
        </limit>
        <dynamics>
          <damping>0.01</damping>
        </dynamics>
      </axis>
    </joint>
    <link name="cable7">
      <pose>2.587628 1.621700 2.721146 2.689439 -0.811545 -2.158486</pose>
      <visual name="visual">
        <geometry>
          <cylinder>
            <radius>0.005</radius>
            <length>8.78919791562</length>
          </cylinder>
        </geometry>
        <material>
          <script>
            <uri>file://media/materials/scripts/kitchen.material</uri>
            <name>Gazebo/Black</name>
          </script>
        </material>
      </visual>
      <inertial>
        <inertia>
          <ixx>0.001</ixx>
          <iyy>0.001</iyy>
          <izz>0.001</izz>
          <ixy>0</ixy>
          <ixz>0</ixz>
          <iyz>0</iyz>
        </inertia>
        <mass>0.001</mass>
      </inertial>
    </link>
    <link name="virt_X7">
      <inertial>
        <inertia>
          <ixx>0.001</ixx>
          <iyy>0.001</iyy>
          <izz>0.001</izz>
          <ixy>0</ixy>
          <ixz>0</ixz>
          <iyz>0</iyz>
        </inertia>
        <mass>0.001</mass>
      </inertial>
      <pose>3.500000 2.000000 3.500000 2.689439 -0.811545 -2.158486</pose>
    </link>
    <joint name="rev_X7" type="revolute">
      <pose>0 0 0 2.689439 -0.811545 -2.158486</pose>
      <parent>frame</parent>
      <child>virt_X7</child>
      <axis>
        <xyz>-0.381665 -0.572885 0.725351</xyz>
        <limit>
          <effort>100</effort>
          <velocity>10</velocity>
        </limit>
        <dynamics>
          <damping>0.01</damping>
        </dynamics>
      </axis>
    </joint>
    <link name="virt_Y7">
      <inertial>
        <inertia>
          <ixx>0.001</ixx>
          <iyy>0.001</iyy>
          <izz>0.001</izz>
          <ixy>0</ixy>
          <ixz>0</ixz>
          <iyz>0</iyz>
        </inertia>
        <mass>0.001</mass>
      </inertial>
      <pose>3.500000 2.000000 3.500000 2.689439 -0.811545 -2.158486</pose>
    </link>
    <joint name="rev_Y7" type="revolute">
      <pose>0 0 0 2.689439 -0.811545 -2.158486</pose>
      <parent>virt_X7</parent>
      <child>virt_Y7</child>
      <axis>
        <xyz>-0.572885 0.762462 0.300755</xyz>
        <limit>
          <effort>100</effort>
          <velocity>10</velocity>
        </limit>
        <dynamics>
          <damping>0.01</damping>
        </dynamics>
      </axis>
    </joint>
    <joint name="cable7" type="prismatic">
      <pose>0 0 -0.977929 2.689439 -0.811545 -2.158486</pose>
      <parent>virt_Y7</parent>
      <child>cable7</child>
      <axis>
        <xyz>0.725351 0.300755 0.619202</xyz>
        <limit>
          <lower>-4.39459895781</lower>
          <upper>4.39459895781</upper>
          <effort>10000</effort>
          <velocity>10</velocity>
        </limit>
        <dynamics>
          <damping>1</damping>
        </dynamics>
      </axis>
    </joint>
    <link name="virt_Xpf7">
      <inertial>
        <inertia>
          <ixx>0.001</ixx>
          <iyy>0.001</iyy>
          <izz>0.001</izz>
          <ixy>0</ixy>
          <ixz>0</ixz>
          <iyz>0</iyz>
        </inertia>
        <mass>0.001</mass>
      </inertial>
      <pose>-0.600000 0.300000 0.000000 2.689439 -0.811545 -2.158486</pose>
    </link>
    <joint name="rev_Xpf7" type="revolute">
      <pose>0 0 0 2.689439 -0.811545 -2.158486</pose>
      <parent>platform</parent>
      <child>virt_Xpf7</child>
      <axis>
        <xyz>1 0 0</xyz>
        <limit>
          <effort>100</effort>
          <velocity>10</velocity>
        </limit>
        <dynamics>
          <damping>0.01</damping>
        </dynamics>
      </axis>
    </joint>
    <link name="virt_Ypf7">
      <inertial>
        <inertia>
          <ixx>0.001</ixx>
          <iyy>0.001</iyy>
          <izz>0.001</izz>
          <ixy>0</ixy>
          <ixz>0</ixz>
          <iyz>0</iyz>
        </inertia>
        <mass>0.001</mass>
      </inertial>
      <pose>-0.600000 0.300000 0.000000 2.689439 -0.811545 -2.158486</pose>
    </link>
    <joint name="rev_Ypf7" type="revolute">
      <pose>0 0 0 2.689439 -0.811545 -2.158486</pose>
      <parent>virt_Xpf7</parent>
      <child>virt_Ypf7</child>
      <axis>
        <xyz>0 1 0</xyz>
        <limit>
          <effort>100</effort>
          <velocity>10</velocity>
        </limit>
        <dynamics>
          <damping>0.01</damping>
        </dynamics>
      </axis>
    </joint>
    <joint name="rev_Zpf7" type="revolute">
      <pose>0 0 0 2.689439 -0.811545 -2.158486</pose>
      <child>virt_Ypf7</child>
      <parent>cable7</parent>
      <axis>
        <xyz>0 0 1</xyz>
        <limit>
          <effort>100</effort>
          <velocity>10</velocity>
        </limit>
        <dynamics>
          <damping>0.01</damping>
        </dynamics>
      </axis>
    </joint>
    <plugin filename="libcdpr_plugin.so" name="cdpr_plugin"/>
  </model>
</sdf>
