<?xml version="1.0"?>
<sdf version="1.4">
  <model name="cube">
    <!--Definition of the robot frame-->
    <link name="frame">
      <pose>0 0 0 0 0 0</pose>
      <inertial>
        <inertia>
          <ixx>50000.0</ixx>
          <ixy>0</ixy>
          <ixz>0</ixz>
          <iyy>50000.0</iyy>
          <iyz>0</iyz>
          <izz>50000.0</izz>
        </inertia>
        <mass>100000</mass>
      </inertial>
      <visual name="visual1">
        <geometry>
          <cylinder>
            <radius>0.02</radius>
            <length>4.0</length>
          </cylinder>
        </geometry>
        <pose>-2.000000 -2.000000 2.000000 0.000000 0.000000 0.000000</pose>
        <material>
          <script>
            <uri>file://media/materials/scripts/kitchen.material</uri>
            <name>Gazebo/Yellow</name>
          </script>
        </material>
      </visual>
      <collision name="collision1">
        <geometry>
          <cylinder>
            <radius>0.02</radius>
          </cylinder>
        </geometry>
        <pose>-2.000000 -2.000000 2.000000 0.000000 0.000000 0.000000</pose>
      </collision>
      <visual name="visual2">
        <geometry>
          <cylinder>
            <radius>0.02</radius>
            <length>4.0</length>
          </cylinder>
        </geometry>
        <pose>-2.000000 0.000000 0.000000 1.570796 0.000000 0.000000</pose>
        <material>
          <script>
            <uri>file://media/materials/scripts/kitchen.material</uri>
            <name>Gazebo/Yellow</name>
          </script>
        </material>
      </visual>
      <collision name="collision2">
        <geometry>
          <cylinder>
            <radius>0.02</radius>
          </cylinder>
        </geometry>
        <pose>-2.000000 0.000000 0.000000 1.570796 0.000000 0.000000</pose>
      </collision>
      <visual name="visual3">
        <geometry>
          <cylinder>
            <radius>0.02</radius>
            <length>4.0</length>
          </cylinder>
        </geometry>
        <pose>0.000000 -2.000000 0.000000 0.000000 1.570796 0.000000</pose>
        <material>
          <script>
            <uri>file://media/materials/scripts/kitchen.material</uri>
            <name>Gazebo/Yellow</name>
          </script>
        </material>
      </visual>
      <collision name="collision3">
        <geometry>
          <cylinder>
            <radius>0.02</radius>
          </cylinder>
        </geometry>
        <pose>0.000000 -2.000000 0.000000 0.000000 1.570796 0.000000</pose>
      </collision>
      <visual name="visual4">
        <geometry>
          <cylinder>
            <radius>0.02</radius>
            <length>4.0</length>
          </cylinder>
        </geometry>
        <pose>-2.000000 0.000000 4.000000 1.570796 0.000000 0.000000</pose>
        <material>
          <script>
            <uri>file://media/materials/scripts/kitchen.material</uri>
            <name>Gazebo/Yellow</name>
          </script>
        </material>
      </visual>
      <collision name="collision4">
        <geometry>
          <cylinder>
            <radius>0.02</radius>
          </cylinder>
        </geometry>
        <pose>-2.000000 0.000000 4.000000 1.570796 0.000000 0.000000</pose>
      </collision>
      <visual name="visual5">
        <geometry>
          <cylinder>
            <radius>0.02</radius>
            <length>4.0</length>
          </cylinder>
        </geometry>
        <pose>0.000000 -2.000000 4.000000 0.000000 1.570796 0.000000</pose>
        <material>
          <script>
            <uri>file://media/materials/scripts/kitchen.material</uri>
            <name>Gazebo/Yellow</name>
          </script>
        </material>
      </visual>
      <collision name="collision5">
        <geometry>
          <cylinder>
            <radius>0.02</radius>
          </cylinder>
        </geometry>
        <pose>0.000000 -2.000000 4.000000 0.000000 1.570796 0.000000</pose>
      </collision>
      <visual name="visual6">
        <geometry>
          <cylinder>
            <radius>0.02</radius>
            <length>4.0</length>
          </cylinder>
        </geometry>
        <pose>-2.000000 2.000000 2.000000 0.000000 0.000000 0.000000</pose>
        <material>
          <script>
            <uri>file://media/materials/scripts/kitchen.material</uri>
            <name>Gazebo/Yellow</name>
          </script>
        </material>
      </visual>
      <collision name="collision6">
        <geometry>
          <cylinder>
            <radius>0.02</radius>
          </cylinder>
        </geometry>
        <pose>-2.000000 2.000000 2.000000 0.000000 0.000000 0.000000</pose>
      </collision>
      <visual name="visual7">
        <geometry>
          <cylinder>
            <radius>0.02</radius>
            <length>4.0</length>
          </cylinder>
        </geometry>
        <pose>0.000000 2.000000 0.000000 0.000000 1.570796 0.000000</pose>
        <material>
          <script>
            <uri>file://media/materials/scripts/kitchen.material</uri>
            <name>Gazebo/Yellow</name>
          </script>
        </material>
      </visual>
      <collision name="collision7">
        <geometry>
          <cylinder>
            <radius>0.02</radius>
          </cylinder>
        </geometry>
        <pose>0.000000 2.000000 0.000000 0.000000 1.570796 0.000000</pose>
      </collision>
      <visual name="visual8">
        <geometry>
          <cylinder>
            <radius>0.02</radius>
            <length>4.0</length>
          </cylinder>
        </geometry>
        <pose>0.000000 2.000000 4.000000 0.000000 1.570796 0.000000</pose>
        <material>
          <script>
            <uri>file://media/materials/scripts/kitchen.material</uri>
            <name>Gazebo/Yellow</name>
          </script>
        </material>
      </visual>
      <collision name="collision8">
        <geometry>
          <cylinder>
            <radius>0.02</radius>
          </cylinder>
        </geometry>
        <pose>0.000000 2.000000 4.000000 0.000000 1.570796 0.000000</pose>
      </collision>
      <visual name="visual9">
        <geometry>
          <cylinder>
            <radius>0.02</radius>
            <length>4.0</length>
          </cylinder>
        </geometry>
        <pose>2.000000 -2.000000 2.000000 0.000000 0.000000 0.000000</pose>
        <material>
          <script>
            <uri>file://media/materials/scripts/kitchen.material</uri>
            <name>Gazebo/Yellow</name>
          </script>
        </material>
      </visual>
      <collision name="collision9">
        <geometry>
          <cylinder>
            <radius>0.02</radius>
          </cylinder>
        </geometry>
        <pose>2.000000 -2.000000 2.000000 0.000000 0.000000 0.000000</pose>
      </collision>
      <visual name="visual10">
        <geometry>
          <cylinder>
            <radius>0.02</radius>
            <length>4.0</length>
          </cylinder>
        </geometry>
        <pose>2.000000 0.000000 0.000000 1.570796 0.000000 0.000000</pose>
        <material>
          <script>
            <uri>file://media/materials/scripts/kitchen.material</uri>
            <name>Gazebo/Yellow</name>
          </script>
        </material>
      </visual>
      <collision name="collision10">
        <geometry>
          <cylinder>
            <radius>0.02</radius>
          </cylinder>
        </geometry>
        <pose>2.000000 0.000000 0.000000 1.570796 0.000000 0.000000</pose>
      </collision>
      <visual name="visual11">
        <geometry>
          <cylinder>
            <radius>0.02</radius>
            <length>4.0</length>
          </cylinder>
        </geometry>
        <pose>2.000000 0.000000 4.000000 1.570796 0.000000 0.000000</pose>
        <material>
          <script>
            <uri>file://media/materials/scripts/kitchen.material</uri>
            <name>Gazebo/Yellow</name>
          </script>
        </material>
      </visual>
      <collision name="collision11">
        <geometry>
          <cylinder>
            <radius>0.02</radius>
          </cylinder>
        </geometry>
        <pose>2.000000 0.000000 4.000000 1.570796 0.000000 0.000000</pose>
      </collision>
      <visual name="visual12">
        <geometry>
          <cylinder>
            <radius>0.02</radius>
            <length>4.0</length>
          </cylinder>
        </geometry>
        <pose>2.000000 2.000000 2.000000 0.000000 0.000000 0.000000</pose>
        <material>
          <script>
            <uri>file://media/materials/scripts/kitchen.material</uri>
            <name>Gazebo/Yellow</name>
          </script>
        </material>
      </visual>
      <collision name="collision12">
        <geometry>
          <cylinder>
            <radius>0.02</radius>
          </cylinder>
        </geometry>
        <pose>2.000000 2.000000 2.000000 0.000000 0.000000 0.000000</pose>
      </collision>
    </link>
    <!--Definition of the robot cables-->
    <!--Definition of the robot platform-->
    <link name="platform">
      <pose>0.000000 0.000000 2.000000 0.000000 0.000000 0.000000</pose>
      <visual name="visualpf">
        <geometry>
          <box>
            <size>0.400000 0.400000 0.000000</size>
          </box>
        </geometry>
        <material>
          <script>
            <uri>file://media/materials/scripts/kitchen.material</uri>
            <name>Gazebo/Blue</name>
          </script>
        </material>
      </visual>
      <collision name="collisionpf">
        <geometry>
          <box>
            <size>0.400000 0.400000 0.000000</size>
          </box>
        </geometry>
      </collision>
      <inertial>
        <inertia>
          <ixx>0.5</ixx>
          <ixy>0</ixy>
          <ixz>0</ixz>
          <iyy>0.5</iyy>
          <iyz>0</iyz>
          <izz>0.5</izz>
        </inertia>
        <mass>1</mass>
      </inertial>
    </link>
    <!--Definition of the robot Ball Joints frame to cable-->
    <!--Definition of the robot Ball Joints platform to cable-->
    <!--Definition of the robot Prismatic Joints-->
    <!--Definition of the robot Ball Joints frame to cable-->
    <!--Definition of the robot Ball Joints platform to cable-->
    <!--Definition of the robot Prismatic Joints-->
    <!--Definition of the robot Ball Joints frame to cable-->
    <!--Definition of the robot Ball Joints platform to cable-->
    <!--Definition of the robot Prismatic Joints-->
    <!--Definition of the robot Ball Joints frame to cable-->
    <!--Definition of the robot Ball Joints platform to cable-->
    <!--Definition of the robot Prismatic Joints-->
    <link name="cable0">
      <pose>-2.200000 -2.200000 4.200000 -2.356194 0.615480 -1.308997</pose>
      <visual name="visual">
        <geometry>
          <cylinder>
            <radius>0.005</radius>
            <length>6.92820323028</length>
          </cylinder>
        </geometry>
        <material>
          <script>
            <uri>file://media/materials/scripts/kitchen.material</uri>
            <name>Gazebo/Black</name>
          </script>
        </material>
      </visual>
      <inertial>
        <inertia>
          <ixx>0.0005</ixx>
          <ixy>0</ixy>
          <ixz>0</ixz>
          <iyy>0.0005</iyy>
          <iyz>0</iyz>
          <izz>0.0005</izz>
        </inertia>
        <mass>0.001</mass>
      </inertial>
    </link>
    <joint name="joint_0_cable1" type="ball">
      <pose>-2.000000 -2.000000 4.000000 0 0 0</pose>
      <parent>frame</parent>
      <child>cable0</child>
      <axis>
        <xyz>0.000000 0.000000 1.000000</xyz>
      </axis>
      <limit>
        <lower>-3.14159265359</lower>
        <upper>3.14159265359</upper>
      </limit>
    </joint>
    <joint name="joint_0_cable2" type="ball">
      <pose>-2.200000 -2.200000 4.200000 0 0 0</pose>
      <parent>platform</parent>
      <child>cable0</child>
      <axis>
        <xyz>0.000000 0.000000 1.000000</xyz>
      </axis>
      <limit>
        <lower>-3.14159265359</lower>
        <upper>3.14159265359</upper>
      </limit>
    </joint>
    <joint name="joint_0_prismatic" type="prismatic">
      <pose>-2.000000 -2.000000 4.000000 0 0 0</pose>
      <parent>frame</parent>
      <child>platform</child>
      <axis>
        <xyz>-2.356194 0.615480 -1.308997</xyz>
      </axis>
      <limit>
        <lower>0</lower>
        <upper>6.92820323028</upper>
        <effort>20</effort>
      </limit>
    </joint>
    <link name="cable1">
      <pose>-2.200000 2.200000 4.200000 2.356194 0.615480 1.308997</pose>
      <visual name="visual">
        <geometry>
          <cylinder>
            <radius>0.005</radius>
            <length>6.92820323028</length>
          </cylinder>
        </geometry>
        <material>
          <script>
            <uri>file://media/materials/scripts/kitchen.material</uri>
            <name>Gazebo/Black</name>
          </script>
        </material>
      </visual>
      <inertial>
        <inertia>
          <ixx>0.0005</ixx>
          <ixy>0</ixy>
          <ixz>0</ixz>
          <iyy>0.0005</iyy>
          <iyz>0</iyz>
          <izz>0.0005</izz>
        </inertia>
        <mass>0.001</mass>
      </inertial>
    </link>
    <joint name="joint_1_cable1" type="ball">
      <pose>-2.000000 2.000000 4.000000 0 0 0</pose>
      <parent>frame</parent>
      <child>cable1</child>
      <axis>
        <xyz>0.000000 0.000000 1.000000</xyz>
      </axis>
      <limit>
        <lower>-3.14159265359</lower>
        <upper>3.14159265359</upper>
      </limit>
    </joint>
    <joint name="joint_1_cable2" type="ball">
      <pose>-2.200000 2.200000 4.200000 0 0 0</pose>
      <parent>platform</parent>
      <child>cable1</child>
      <axis>
        <xyz>0.000000 0.000000 1.000000</xyz>
      </axis>
      <limit>
        <lower>-3.14159265359</lower>
        <upper>3.14159265359</upper>
      </limit>
    </joint>
    <joint name="joint_1_prismatic" type="prismatic">
      <pose>-2.000000 2.000000 4.000000 0 0 0</pose>
      <parent>frame</parent>
      <child>platform</child>
      <axis>
        <xyz>2.356194 0.615480 1.308997</xyz>
      </axis>
      <limit>
        <lower>0</lower>
        <upper>6.92820323028</upper>
        <effort>20</effort>
      </limit>
    </joint>
    <link name="cable2">
      <pose>2.200000 2.200000 4.200000 2.356194 -0.615480 -1.308997</pose>
      <visual name="visual">
        <geometry>
          <cylinder>
            <radius>0.005</radius>
            <length>6.92820323028</length>
          </cylinder>
        </geometry>
        <material>
          <script>
            <uri>file://media/materials/scripts/kitchen.material</uri>
            <name>Gazebo/Black</name>
          </script>
        </material>
      </visual>
      <inertial>
        <inertia>
          <ixx>0.0005</ixx>
          <ixy>0</ixy>
          <ixz>0</ixz>
          <iyy>0.0005</iyy>
          <iyz>0</iyz>
          <izz>0.0005</izz>
        </inertia>
        <mass>0.001</mass>
      </inertial>
    </link>
    <joint name="joint_2_cable1" type="ball">
      <pose>2.000000 2.000000 4.000000 0 0 0</pose>
      <parent>frame</parent>
      <child>cable2</child>
      <axis>
        <xyz>0.000000 0.000000 1.000000</xyz>
      </axis>
      <limit>
        <lower>-3.14159265359</lower>
        <upper>3.14159265359</upper>
      </limit>
    </joint>
    <joint name="joint_2_cable2" type="ball">
      <pose>2.200000 2.200000 4.200000 0 0 0</pose>
      <parent>platform</parent>
      <child>cable2</child>
      <axis>
        <xyz>0.000000 0.000000 1.000000</xyz>
      </axis>
      <limit>
        <lower>-3.14159265359</lower>
        <upper>3.14159265359</upper>
      </limit>
    </joint>
    <joint name="joint_2_prismatic" type="prismatic">
      <pose>2.000000 2.000000 4.000000 0 0 0</pose>
      <parent>frame</parent>
      <child>platform</child>
      <axis>
        <xyz>2.356194 -0.615480 -1.308997</xyz>
      </axis>
      <limit>
        <lower>0</lower>
        <upper>6.92820323028</upper>
        <effort>20</effort>
      </limit>
    </joint>
    <link name="cable3">
      <pose>2.200000 -2.200000 4.200000 -2.356194 -0.615480 1.308997</pose>
      <visual name="visual">
        <geometry>
          <cylinder>
            <radius>0.005</radius>
            <length>6.92820323028</length>
          </cylinder>
        </geometry>
        <material>
          <script>
            <uri>file://media/materials/scripts/kitchen.material</uri>
            <name>Gazebo/Black</name>
          </script>
        </material>
      </visual>
      <inertial>
        <inertia>
          <ixx>0.0005</ixx>
          <ixy>0</ixy>
          <ixz>0</ixz>
          <iyy>0.0005</iyy>
          <iyz>0</iyz>
          <izz>0.0005</izz>
        </inertia>
        <mass>0.001</mass>
      </inertial>
    </link>
    <joint name="joint_3_cable1" type="ball">
      <pose>2.000000 -2.000000 4.000000 0 0 0</pose>
      <parent>frame</parent>
      <child>cable3</child>
      <axis>
        <xyz>0.000000 0.000000 1.000000</xyz>
      </axis>
      <limit>
        <lower>-3.14159265359</lower>
        <upper>3.14159265359</upper>
      </limit>
    </joint>
    <joint name="joint_3_cable2" type="ball">
      <pose>2.200000 -2.200000 4.200000 0 0 0</pose>
      <parent>platform</parent>
      <child>cable3</child>
      <axis>
        <xyz>0.000000 0.000000 1.000000</xyz>
      </axis>
      <limit>
        <lower>-3.14159265359</lower>
        <upper>3.14159265359</upper>
      </limit>
    </joint>
    <joint name="joint_3_prismatic" type="prismatic">
      <pose>2.000000 -2.000000 4.000000 0 0 0</pose>
      <parent>frame</parent>
      <child>platform</child>
      <axis>
        <xyz>-2.356194 -0.615480 1.308997</xyz>
      </axis>
      <limit>
        <lower>0</lower>
        <upper>6.92820323028</upper>
        <effort>20</effort>
      </limit>
    </joint>
  </model>
</sdf>
