<?xml version="1.0"?>
<sdf version="1.4">
  <model name="surabaya">
    <!--Definition of the robot frame-->
    <link name="frame">
      <pose>0 0 0.02 0 0 0</pose>
      <inertial>
        <inertia>
          <ixx>100000</ixx>
          <iyy>100000</iyy>
          <izz>100000</izz>
          <ixy>0</ixy>
          <ixz>0</ixz>
          <iyz>0</iyz>
        </inertia>
        <mass>100000</mass>
      </inertial>
      <visual name="visual0">
        <geometry>
          <cylinder>
            <radius>0.02</radius>
            <length>3.5</length>
          </cylinder>
        </geometry>
        <pose>-3.500000 -2.000000 1.750000 0.000000 0.000000 0.000000</pose>
        <material>
          <script>
            <uri>file://media/materials/scripts/kitchen.material</uri>
            <name>Gazebo/Grey</name>
          </script>
        </material>
      </visual>
      <collision name="collision0">
        <geometry>
          <cylinder>
            <radius>0.02</radius>
          </cylinder>
        </geometry>
        <pose>-3.500000 -2.000000 1.750000 0.000000 0.000000 0.000000</pose>
      </collision>
      <visual name="visual1">
        <geometry>
          <cylinder>
            <radius>0.02</radius>
            <length>3.5</length>
          </cylinder>
        </geometry>
        <pose>3.500000 -2.000000 1.750000 0.000000 0.000000 0.000000</pose>
        <material>
          <script>
            <uri>file://media/materials/scripts/kitchen.material</uri>
            <name>Gazebo/Grey</name>
          </script>
        </material>
      </visual>
      <collision name="collision1">
        <geometry>
          <cylinder>
            <radius>0.02</radius>
          </cylinder>
        </geometry>
        <pose>3.500000 -2.000000 1.750000 0.000000 0.000000 0.000000</pose>
      </collision>
      <visual name="visual2">
        <geometry>
          <cylinder>
            <radius>0.02</radius>
            <length>3.5</length>
          </cylinder>
        </geometry>
        <pose>-3.500000 2.000000 1.750000 0.000000 0.000000 0.000000</pose>
        <material>
          <script>
            <uri>file://media/materials/scripts/kitchen.material</uri>
            <name>Gazebo/Grey</name>
          </script>
        </material>
      </visual>
      <collision name="collision2">
        <geometry>
          <cylinder>
            <radius>0.02</radius>
          </cylinder>
        </geometry>
        <pose>-3.500000 2.000000 1.750000 0.000000 0.000000 0.000000</pose>
      </collision>
      <visual name="visual3">
        <geometry>
          <cylinder>
            <radius>0.02</radius>
            <length>3.5</length>
          </cylinder>
        </geometry>
        <pose>3.500000 2.000000 1.750000 0.000000 0.000000 0.000000</pose>
        <material>
          <script>
            <uri>file://media/materials/scripts/kitchen.material</uri>
            <name>Gazebo/Grey</name>
          </script>
        </material>
      </visual>
      <collision name="collision3">
        <geometry>
          <cylinder>
            <radius>0.02</radius>
          </cylinder>
        </geometry>
        <pose>3.500000 2.000000 1.750000 0.000000 0.000000 0.000000</pose>
      </collision>
    </link>
    <!--Definition of the robot cables-->
    <!--Definition of the robot platform-->
    <link name="platform">
      <pose>0.900000 0.900000 0.220000 0.000000 0.000000 0.000000</pose>
      <visual name="visualpf">
        <geometry>
          <box>
            <size>1.200000 0.600000 0.400000</size>
          </box>
        </geometry>
        <material>
          <script>
            <uri>file://media/materials/scripts/kitchen.material</uri>
            <name>Gazebo/Blue</name>
          </script>
        </material>
      </visual>
      <collision name="collisionpf">
        <geometry>
          <box>
            <size>1.200000 0.600000 0.400000</size>
          </box>
        </geometry>
      </collision>
      <inertial>
        <inertia>
          <ixx>100.0</ixx>
          <iyy>100.0</iyy>
          <izz>100.0</izz>
          <ixy>0.0</ixy>
          <ixz>0.0</ixz>
          <iyz>0.0</iyz>
        </inertia>
        <mass>150</mass>
      </inertial>
    </link>
    <link name="cable0">
      <pose>-1.814444 -1.123511 2.326853 -2.499933 0.855488 -1.881845</pose>
      <visual name="visual">
        <geometry>
          <cylinder>
            <radius>0.005</radius>
            <length>8.78125275801</length>
          </cylinder>
        </geometry>
        <material>
          <script>
            <uri>file://media/materials/scripts/kitchen.material</uri>
            <name>Gazebo/Black</name>
          </script>
        </material>
      </visual>
      <inertial>
        <inertia>
          <ixx>0.001</ixx>
          <iyy>0.001</iyy>
          <izz>0.001</izz>
          <ixy>0</ixy>
          <ixz>0</ixz>
          <iyz>0</iyz>
        </inertia>
        <mass>0.001</mass>
      </inertial>
    </link>
    <link name="virt_X0">
      <inertial>
        <inertia>
          <ixx>0.001</ixx>
          <iyy>0.001</iyy>
          <izz>0.001</izz>
          <ixy>0</ixy>
          <ixz>0</ixz>
          <iyz>0</iyz>
        </inertia>
        <mass>0.001</mass>
      </inertial>
      <pose>-3.500000 -2.000000 3.500000 -2.499933 0.855488 -1.881845</pose>
    </link>
    <joint name="rev_X0" type="revolute">
      <pose>0 0 0 -2.499933 0.855488 -1.881845</pose>
      <parent>frame</parent>
      <child>virt_X0</child>
      <axis>
        <xyz>-0.200727 -0.624378 -0.754891</xyz>
        <limit>
          <effort>1000</effort>
          <velocity>10</velocity>
        </limit>
        <dynamics>
          <damping>0.01</damping>
        </dynamics>
      </axis>
    </joint>
    <link name="virt_Y0">
      <inertial>
        <inertia>
          <ixx>0.001</ixx>
          <iyy>0.001</iyy>
          <izz>0.001</izz>
          <ixy>0</ixy>
          <ixz>0</ixz>
          <iyz>0</iyz>
        </inertia>
        <mass>0.001</mass>
      </inertial>
      <pose>-3.500000 -2.000000 3.500000 -2.499933 0.855488 -1.881845</pose>
    </link>
    <joint name="rev_Y0" type="revolute">
      <pose>0 0 0 -2.499933 0.855488 -1.881845</pose>
      <parent>virt_X0</parent>
      <child>virt_Y0</child>
      <axis>
        <xyz>-0.624378 0.675323 -0.392543</xyz>
        <limit>
          <effort>1000</effort>
          <velocity>10</velocity>
        </limit>
        <dynamics>
          <damping>0.01</damping>
        </dynamics>
      </axis>
    </joint>
    <joint name="cable0" type="prismatic">
      <pose>0 0 -1.480129 -2.499933 0.855488 -1.881845</pose>
      <parent>virt_Y0</parent>
      <child>cable0</child>
      <axis>
        <xyz>-0.754891 -0.392543 0.525404</xyz>
        <limit>
          <lower>-4.390626379</lower>
          <upper>4.390626379</upper>
          <effort>10000</effort>
          <velocity>10</velocity>
        </limit>
        <dynamics>
          <damping>1</damping>
        </dynamics>
      </axis>
    </joint>
    <link name="virt_Xpf0">
      <inertial>
        <inertia>
          <ixx>0.001</ixx>
          <iyy>0.001</iyy>
          <izz>0.001</izz>
          <ixy>0</ixy>
          <ixz>0</ixz>
          <iyz>0</iyz>
        </inertia>
        <mass>0.001</mass>
      </inertial>
      <pose>1.500000 0.600000 0.020000 -2.499933 0.855488 -1.881845</pose>
    </link>
    <joint name="rev_Xpf0" type="revolute">
      <pose>0 0 0 -2.499933 0.855488 -1.881845</pose>
      <parent>platform</parent>
      <child>virt_Xpf0</child>
      <axis>
        <xyz>1 0 0</xyz>
        <limit>
          <effort>1000</effort>
          <velocity>10</velocity>
        </limit>
        <dynamics>
          <damping>0.01</damping>
        </dynamics>
      </axis>
    </joint>
    <link name="virt_Ypf0">
      <inertial>
        <inertia>
          <ixx>0.001</ixx>
          <iyy>0.001</iyy>
          <izz>0.001</izz>
          <ixy>0</ixy>
          <ixz>0</ixz>
          <iyz>0</iyz>
        </inertia>
        <mass>0.001</mass>
      </inertial>
      <pose>1.500000 0.600000 0.020000 -2.499933 0.855488 -1.881845</pose>
    </link>
    <joint name="rev_Ypf0" type="revolute">
      <pose>0 0 0 -2.499933 0.855488 -1.881845</pose>
      <parent>virt_Xpf0</parent>
      <child>virt_Ypf0</child>
      <axis>
        <xyz>0 1 0</xyz>
        <limit>
          <effort>1000</effort>
          <velocity>10</velocity>
        </limit>
        <dynamics>
          <damping>0.01</damping>
        </dynamics>
      </axis>
    </joint>
    <joint name="rev_Zpf0" type="revolute">
      <pose>0 0 0 -2.499933 0.855488 -1.881845</pose>
      <child>virt_Ypf0</child>
      <parent>cable0</parent>
      <axis>
        <xyz>0 0 1</xyz>
        <limit>
          <effort>1000</effort>
          <velocity>10</velocity>
        </limit>
        <dynamics>
          <damping>0.01</damping>
        </dynamics>
      </axis>
    </joint>
    <link name="cable1">
      <pose>3.030015 -1.618137 3.047639 -2.440501 -0.671017 1.523332</pose>
      <visual name="visual">
        <geometry>
          <cylinder>
            <radius>0.005</radius>
            <length>8.78125275801</length>
          </cylinder>
        </geometry>
        <material>
          <script>
            <uri>file://media/materials/scripts/kitchen.material</uri>
            <name>Gazebo/Black</name>
          </script>
        </material>
      </visual>
      <inertial>
        <inertia>
          <ixx>0.001</ixx>
          <iyy>0.001</iyy>
          <izz>0.001</izz>
          <ixy>0</ixy>
          <ixz>0</ixz>
          <iyz>0</iyz>
        </inertia>
        <mass>0.001</mass>
      </inertial>
    </link>
    <link name="virt_X1">
      <inertial>
        <inertia>
          <ixx>0.001</ixx>
          <iyy>0.001</iyy>
          <izz>0.001</izz>
          <ixy>0</ixy>
          <ixz>0</ixz>
          <iyz>0</iyz>
        </inertia>
        <mass>0.001</mass>
      </inertial>
      <pose>3.500000 -2.000000 3.500000 -2.440501 -0.671017 1.523332</pose>
    </link>
    <joint name="rev_X1" type="revolute">
      <pose>0 0 0 -2.440501 -0.671017 1.523332</pose>
      <parent>frame</parent>
      <child>virt_X1</child>
      <axis>
        <xyz>0.037159 0.782308 0.621783</xyz>
        <limit>
          <effort>1000</effort>
          <velocity>10</velocity>
        </limit>
        <dynamics>
          <damping>0.01</damping>
        </dynamics>
      </axis>
    </joint>
    <link name="virt_Y1">
      <inertial>
        <inertia>
          <ixx>0.001</ixx>
          <iyy>0.001</iyy>
          <izz>0.001</izz>
          <ixy>0</ixy>
          <ixz>0</ixz>
          <iyz>0</iyz>
        </inertia>
        <mass>0.001</mass>
      </inertial>
      <pose>3.500000 -2.000000 3.500000 -2.440501 -0.671017 1.523332</pose>
    </link>
    <joint name="rev_Y1" type="revolute">
      <pose>0 0 0 -2.440501 -0.671017 1.523332</pose>
      <parent>virt_X1</parent>
      <child>virt_Y1</child>
      <axis>
        <xyz>0.782308 0.364375 -0.505198</xyz>
        <limit>
          <effort>1000</effort>
          <velocity>10</velocity>
        </limit>
        <dynamics>
          <damping>0.01</damping>
        </dynamics>
      </axis>
    </joint>
    <joint name="cable1" type="prismatic">
      <pose>0 0 -0.644853 -2.440501 -0.671017 1.523332</pose>
      <parent>virt_Y1</parent>
      <child>cable1</child>
      <axis>
        <xyz>0.621783 -0.505198 0.598466</xyz>
        <limit>
          <lower>-4.390626379</lower>
          <upper>4.390626379</upper>
          <effort>10000</effort>
          <velocity>10</velocity>
        </limit>
        <dynamics>
          <damping>1</damping>
        </dynamics>
      </axis>
    </joint>
    <link name="virt_Xpf1">
      <inertial>
        <inertia>
          <ixx>0.001</ixx>
          <iyy>0.001</iyy>
          <izz>0.001</izz>
          <ixy>0</ixy>
          <ixz>0</ixz>
          <iyz>0</iyz>
        </inertia>
        <mass>0.001</mass>
      </inertial>
      <pose>0.300000 0.600000 0.420000 -2.440501 -0.671017 1.523332</pose>
    </link>
    <joint name="rev_Xpf1" type="revolute">
      <pose>0 0 0 -2.440501 -0.671017 1.523332</pose>
      <parent>platform</parent>
      <child>virt_Xpf1</child>
      <axis>
        <xyz>1 0 0</xyz>
        <limit>
          <effort>1000</effort>
          <velocity>10</velocity>
        </limit>
        <dynamics>
          <damping>0.01</damping>
        </dynamics>
      </axis>
    </joint>
    <link name="virt_Ypf1">
      <inertial>
        <inertia>
          <ixx>0.001</ixx>
          <iyy>0.001</iyy>
          <izz>0.001</izz>
          <ixy>0</ixy>
          <ixz>0</ixz>
          <iyz>0</iyz>
        </inertia>
        <mass>0.001</mass>
      </inertial>
      <pose>0.300000 0.600000 0.420000 -2.440501 -0.671017 1.523332</pose>
    </link>
    <joint name="rev_Ypf1" type="revolute">
      <pose>0 0 0 -2.440501 -0.671017 1.523332</pose>
      <parent>virt_Xpf1</parent>
      <child>virt_Ypf1</child>
      <axis>
        <xyz>0 1 0</xyz>
        <limit>
          <effort>1000</effort>
          <velocity>10</velocity>
        </limit>
        <dynamics>
          <damping>0.01</damping>
        </dynamics>
      </axis>
    </joint>
    <joint name="rev_Zpf1" type="revolute">
      <pose>0 0 0 -2.440501 -0.671017 1.523332</pose>
      <child>virt_Ypf1</child>
      <parent>cable1</parent>
      <axis>
        <xyz>0 0 1</xyz>
        <limit>
          <effort>1000</effort>
          <velocity>10</velocity>
        </limit>
        <dynamics>
          <damping>0.01</damping>
        </dynamics>
      </axis>
    </joint>
    <link name="cable2">
      <pose>-2.824701 1.751206 2.881568 2.759106 0.791880 2.274100</pose>
      <visual name="visual">
        <geometry>
          <cylinder>
            <radius>0.005</radius>
            <length>8.78125275801</length>
          </cylinder>
        </geometry>
        <material>
          <script>
            <uri>file://media/materials/scripts/kitchen.material</uri>
            <name>Gazebo/Black</name>
          </script>
        </material>
      </visual>
      <inertial>
        <inertia>
          <ixx>0.001</ixx>
          <iyy>0.001</iyy>
          <izz>0.001</izz>
          <ixy>0</ixy>
          <ixz>0</ixz>
          <iyz>0</iyz>
        </inertia>
        <mass>0.001</mass>
      </inertial>
    </link>
    <link name="virt_X2">
      <inertial>
        <inertia>
          <ixx>0.001</ixx>
          <iyy>0.001</iyy>
          <izz>0.001</izz>
          <ixy>0</ixy>
          <ixz>0</ixz>
          <iyz>0</iyz>
        </inertia>
        <mass>0.001</mass>
      </inertial>
      <pose>-3.500000 2.000000 3.500000 2.759106 0.791880 2.274100</pose>
    </link>
    <joint name="rev_X2" type="revolute">
      <pose>0 0 0 2.759106 0.791880 2.274100</pose>
      <parent>frame</parent>
      <child>virt_X2</child>
      <axis>
        <xyz>-0.454341 0.535810 -0.711675</xyz>
        <limit>
          <effort>1000</effort>
          <velocity>10</velocity>
        </limit>
        <dynamics>
          <damping>0.01</damping>
        </dynamics>
      </axis>
    </joint>
    <link name="virt_Y2">
      <inertial>
        <inertia>
          <ixx>0.001</ixx>
          <iyy>0.001</iyy>
          <izz>0.001</izz>
          <ixy>0</ixy>
          <ixz>0</ixz>
          <iyz>0</iyz>
        </inertia>
        <mass>0.001</mass>
      </inertial>
      <pose>-3.500000 2.000000 3.500000 2.759106 0.791880 2.274100</pose>
    </link>
    <joint name="rev_Y2" type="revolute">
      <pose>0 0 0 2.759106 0.791880 2.274100</pose>
      <parent>virt_X2</parent>
      <child>virt_Y2</child>
      <axis>
        <xyz>0.535810 0.802596 0.262196</xyz>
        <limit>
          <effort>1000</effort>
          <velocity>10</velocity>
        </limit>
        <dynamics>
          <damping>0.01</damping>
        </dynamics>
      </axis>
    </joint>
    <joint name="cable2" type="prismatic">
      <pose>0 0 -0.780260 2.759106 0.791880 2.274100</pose>
      <parent>virt_Y2</parent>
      <child>cable2</child>
      <axis>
        <xyz>-0.711675 0.262196 0.651745</xyz>
        <limit>
          <lower>-4.390626379</lower>
          <upper>4.390626379</upper>
          <effort>10000</effort>
          <velocity>10</velocity>
        </limit>
        <dynamics>
          <damping>1</damping>
        </dynamics>
      </axis>
    </joint>
    <link name="virt_Xpf2">
      <inertial>
        <inertia>
          <ixx>0.001</ixx>
          <iyy>0.001</iyy>
          <izz>0.001</izz>
          <ixy>0</ixy>
          <ixz>0</ixz>
          <iyz>0</iyz>
        </inertia>
        <mass>0.001</mass>
      </inertial>
      <pose>0.300000 0.600000 0.020000 2.759106 0.791880 2.274100</pose>
    </link>
    <joint name="rev_Xpf2" type="revolute">
      <pose>0 0 0 2.759106 0.791880 2.274100</pose>
      <parent>platform</parent>
      <child>virt_Xpf2</child>
      <axis>
        <xyz>1 0 0</xyz>
        <limit>
          <effort>1000</effort>
          <velocity>10</velocity>
        </limit>
        <dynamics>
          <damping>0.01</damping>
        </dynamics>
      </axis>
    </joint>
    <link name="virt_Ypf2">
      <inertial>
        <inertia>
          <ixx>0.001</ixx>
          <iyy>0.001</iyy>
          <izz>0.001</izz>
          <ixy>0</ixy>
          <ixz>0</ixz>
          <iyz>0</iyz>
        </inertia>
        <mass>0.001</mass>
      </inertial>
      <pose>0.300000 0.600000 0.020000 2.759106 0.791880 2.274100</pose>
    </link>
    <joint name="rev_Ypf2" type="revolute">
      <pose>0 0 0 2.759106 0.791880 2.274100</pose>
      <parent>virt_Xpf2</parent>
      <child>virt_Ypf2</child>
      <axis>
        <xyz>0 1 0</xyz>
        <limit>
          <effort>1000</effort>
          <velocity>10</velocity>
        </limit>
        <dynamics>
          <damping>0.01</damping>
        </dynamics>
      </axis>
    </joint>
    <joint name="rev_Zpf2" type="revolute">
      <pose>0 0 0 2.759106 0.791880 2.274100</pose>
      <child>virt_Ypf2</child>
      <parent>cable2</parent>
      <axis>
        <xyz>0 0 1</xyz>
        <limit>
          <effort>1000</effort>
          <velocity>10</velocity>
        </limit>
        <dynamics>
          <damping>0.01</damping>
        </dynamics>
      </axis>
    </joint>
    <link name="cable3">
      <pose>3.734307 2.164015 3.860833 2.714965 -0.533885 -1.801807</pose>
      <visual name="visual">
        <geometry>
          <cylinder>
            <radius>0.005</radius>
            <length>8.78125275801</length>
          </cylinder>
        </geometry>
        <material>
          <script>
            <uri>file://media/materials/scripts/kitchen.material</uri>
            <name>Gazebo/Black</name>
          </script>
        </material>
      </visual>
      <inertial>
        <inertia>
          <ixx>0.001</ixx>
          <iyy>0.001</iyy>
          <izz>0.001</izz>
          <ixy>0</ixy>
          <ixz>0</ixz>
          <iyz>0</iyz>
        </inertia>
        <mass>0.001</mass>
      </inertial>
    </link>
    <link name="virt_X3">
      <inertial>
        <inertia>
          <ixx>0.001</ixx>
          <iyy>0.001</iyy>
          <izz>0.001</izz>
          <ixy>0</ixy>
          <ixz>0</ixz>
          <iyz>0</iyz>
        </inertia>
        <mass>0.001</mass>
      </inertial>
      <pose>3.500000 2.000000 3.500000 2.714965 -0.533885 -1.801807</pose>
    </link>
    <joint name="rev_X3" type="revolute">
      <pose>0 0 0 2.714965 -0.533885 -1.801807</pose>
      <parent>frame</parent>
      <child>virt_X3</child>
      <axis>
        <xyz>-0.197099 -0.837969 0.508881</xyz>
        <limit>
          <effort>1000</effort>
          <velocity>10</velocity>
        </limit>
        <dynamics>
          <damping>0.01</damping>
        </dynamics>
      </axis>
    </joint>
    <link name="virt_Y3">
      <inertial>
        <inertia>
          <ixx>0.001</ixx>
          <iyy>0.001</iyy>
          <izz>0.001</izz>
          <ixy>0</ixy>
          <ixz>0</ixz>
          <iyz>0</iyz>
        </inertia>
        <mass>0.001</mass>
      </inertial>
      <pose>3.500000 2.000000 3.500000 2.714965 -0.533885 -1.801807</pose>
    </link>
    <joint name="rev_Y3" type="revolute">
      <pose>0 0 0 2.714965 -0.533885 -1.801807</pose>
      <parent>virt_X3</parent>
      <child>virt_Y3</child>
      <axis>
        <xyz>-0.837969 0.413422 0.356217</xyz>
        <limit>
          <effort>1000</effort>
          <velocity>10</velocity>
        </limit>
        <dynamics>
          <damping>0.01</damping>
        </dynamics>
      </axis>
    </joint>
    <joint name="cable3" type="prismatic">
      <pose>0 0 0.514377 2.714965 -0.533885 -1.801807</pose>
      <parent>virt_Y3</parent>
      <child>cable3</child>
      <axis>
        <xyz>0.508881 0.356217 0.783677</xyz>
        <limit>
          <lower>-4.390626379</lower>
          <upper>4.390626379</upper>
          <effort>10000</effort>
          <velocity>10</velocity>
        </limit>
        <dynamics>
          <damping>1</damping>
        </dynamics>
      </axis>
    </joint>
    <link name="virt_Xpf3">
      <inertial>
        <inertia>
          <ixx>0.001</ixx>
          <iyy>0.001</iyy>
          <izz>0.001</izz>
          <ixy>0</ixy>
          <ixz>0</ixz>
          <iyz>0</iyz>
        </inertia>
        <mass>0.001</mass>
      </inertial>
      <pose>1.500000 0.600000 0.420000 2.714965 -0.533885 -1.801807</pose>
    </link>
    <joint name="rev_Xpf3" type="revolute">
      <pose>0 0 0 2.714965 -0.533885 -1.801807</pose>
      <parent>platform</parent>
      <child>virt_Xpf3</child>
      <axis>
        <xyz>1 0 0</xyz>
        <limit>
          <effort>1000</effort>
          <velocity>10</velocity>
        </limit>
        <dynamics>
          <damping>0.01</damping>
        </dynamics>
      </axis>
    </joint>
    <link name="virt_Ypf3">
      <inertial>
        <inertia>
          <ixx>0.001</ixx>
          <iyy>0.001</iyy>
          <izz>0.001</izz>
          <ixy>0</ixy>
          <ixz>0</ixz>
          <iyz>0</iyz>
        </inertia>
        <mass>0.001</mass>
      </inertial>
      <pose>1.500000 0.600000 0.420000 2.714965 -0.533885 -1.801807</pose>
    </link>
    <joint name="rev_Ypf3" type="revolute">
      <pose>0 0 0 2.714965 -0.533885 -1.801807</pose>
      <parent>virt_Xpf3</parent>
      <child>virt_Ypf3</child>
      <axis>
        <xyz>0 1 0</xyz>
        <limit>
          <effort>1000</effort>
          <velocity>10</velocity>
        </limit>
        <dynamics>
          <damping>0.01</damping>
        </dynamics>
      </axis>
    </joint>
    <joint name="rev_Zpf3" type="revolute">
      <pose>0 0 0 2.714965 -0.533885 -1.801807</pose>
      <child>virt_Ypf3</child>
      <parent>cable3</parent>
      <axis>
        <xyz>0 0 1</xyz>
        <limit>
          <effort>1000</effort>
          <velocity>10</velocity>
        </limit>
        <dynamics>
          <damping>0.01</damping>
        </dynamics>
      </axis>
    </joint>
    <plugin filename="libcdpr_plugin.so" name="cdpr_plugin"/>
  </model>
</sdf>
