<?xml version="1.0"?>
<sdf version="1.4">
  <model name="cube">
    <!--Definition of the robot frame-->
    <link name="frame">
      <pose>0 0 0 0 0 0</pose>
      <inertial>
        <inertia>
          <ixx>50000.0</ixx>
          <ixy>0</ixy>
          <ixz>0</ixz>
          <iyy>50000.0</iyy>
          <iyz>0</iyz>
          <izz>50000.0</izz>
        </inertia>
        <mass>100000</mass>
      </inertial>
      <visual name="visual1">
        <geometry>
          <cylinder>
            <radius>0.02</radius>
            <length>4.0</length>
          </cylinder>
        </geometry>
        <pose>-2.500000 -1.500000 2.000000 0.000000 0.000000 0.000000</pose>
        <material>
          <script>
            <uri>file://media/materials/scripts/kitchen.material</uri>
            <name>Gazebo/Black</name>
          </script>
        </material>
      </visual>
      <collision name="collision1">
        <geometry>
          <cylinder>
            <radius>0.02</radius>
          </cylinder>
        </geometry>
        <pose>-2.500000 -1.500000 2.000000 0.000000 0.000000 0.000000</pose>
      </collision>
      <visual name="visual2">
        <geometry>
          <cylinder>
            <radius>0.02</radius>
            <length>3.0</length>
          </cylinder>
        </geometry>
        <pose>-2.500000 0.000000 0.000000 1.570796 0.000000 0.000000</pose>
        <material>
          <script>
            <uri>file://media/materials/scripts/kitchen.material</uri>
            <name>Gazebo/Black</name>
          </script>
        </material>
      </visual>
      <collision name="collision2">
        <geometry>
          <cylinder>
            <radius>0.02</radius>
          </cylinder>
        </geometry>
        <pose>-2.500000 0.000000 0.000000 1.570796 0.000000 0.000000</pose>
      </collision>
      <visual name="visual3">
        <geometry>
          <cylinder>
            <radius>0.02</radius>
            <length>5.0</length>
          </cylinder>
        </geometry>
        <pose>0.000000 -1.500000 0.000000 0.000000 1.570796 0.000000</pose>
        <material>
          <script>
            <uri>file://media/materials/scripts/kitchen.material</uri>
            <name>Gazebo/Black</name>
          </script>
        </material>
      </visual>
      <collision name="collision3">
        <geometry>
          <cylinder>
            <radius>0.02</radius>
          </cylinder>
        </geometry>
        <pose>0.000000 -1.500000 0.000000 0.000000 1.570796 0.000000</pose>
      </collision>
      <visual name="visual4">
        <geometry>
          <cylinder>
            <radius>0.02</radius>
            <length>3.0</length>
          </cylinder>
        </geometry>
        <pose>-2.500000 0.000000 4.000000 1.570796 0.000000 0.000000</pose>
        <material>
          <script>
            <uri>file://media/materials/scripts/kitchen.material</uri>
            <name>Gazebo/Black</name>
          </script>
        </material>
      </visual>
      <collision name="collision4">
        <geometry>
          <cylinder>
            <radius>0.02</radius>
          </cylinder>
        </geometry>
        <pose>-2.500000 0.000000 4.000000 1.570796 0.000000 0.000000</pose>
      </collision>
      <visual name="visual5">
        <geometry>
          <cylinder>
            <radius>0.02</radius>
            <length>5.0</length>
          </cylinder>
        </geometry>
        <pose>0.000000 -1.500000 4.000000 0.000000 1.570796 0.000000</pose>
        <material>
          <script>
            <uri>file://media/materials/scripts/kitchen.material</uri>
            <name>Gazebo/Black</name>
          </script>
        </material>
      </visual>
      <collision name="collision5">
        <geometry>
          <cylinder>
            <radius>0.02</radius>
          </cylinder>
        </geometry>
        <pose>0.000000 -1.500000 4.000000 0.000000 1.570796 0.000000</pose>
      </collision>
      <visual name="visual6">
        <geometry>
          <cylinder>
            <radius>0.02</radius>
            <length>4.0</length>
          </cylinder>
        </geometry>
        <pose>-2.500000 1.500000 2.000000 0.000000 0.000000 0.000000</pose>
        <material>
          <script>
            <uri>file://media/materials/scripts/kitchen.material</uri>
            <name>Gazebo/Black</name>
          </script>
        </material>
      </visual>
      <collision name="collision6">
        <geometry>
          <cylinder>
            <radius>0.02</radius>
          </cylinder>
        </geometry>
        <pose>-2.500000 1.500000 2.000000 0.000000 0.000000 0.000000</pose>
      </collision>
      <visual name="visual7">
        <geometry>
          <cylinder>
            <radius>0.02</radius>
            <length>5.0</length>
          </cylinder>
        </geometry>
        <pose>0.000000 1.500000 0.000000 0.000000 1.570796 0.000000</pose>
        <material>
          <script>
            <uri>file://media/materials/scripts/kitchen.material</uri>
            <name>Gazebo/Black</name>
          </script>
        </material>
      </visual>
      <collision name="collision7">
        <geometry>
          <cylinder>
            <radius>0.02</radius>
          </cylinder>
        </geometry>
        <pose>0.000000 1.500000 0.000000 0.000000 1.570796 0.000000</pose>
      </collision>
      <visual name="visual8">
        <geometry>
          <cylinder>
            <radius>0.02</radius>
            <length>5.0</length>
          </cylinder>
        </geometry>
        <pose>0.000000 1.500000 4.000000 0.000000 1.570796 0.000000</pose>
        <material>
          <script>
            <uri>file://media/materials/scripts/kitchen.material</uri>
            <name>Gazebo/Black</name>
          </script>
        </material>
      </visual>
      <collision name="collision8">
        <geometry>
          <cylinder>
            <radius>0.02</radius>
          </cylinder>
        </geometry>
        <pose>0.000000 1.500000 4.000000 0.000000 1.570796 0.000000</pose>
      </collision>
      <visual name="visual9">
        <geometry>
          <cylinder>
            <radius>0.02</radius>
            <length>4.0</length>
          </cylinder>
        </geometry>
        <pose>2.500000 -1.500000 2.000000 0.000000 0.000000 0.000000</pose>
        <material>
          <script>
            <uri>file://media/materials/scripts/kitchen.material</uri>
            <name>Gazebo/Black</name>
          </script>
        </material>
      </visual>
      <collision name="collision9">
        <geometry>
          <cylinder>
            <radius>0.02</radius>
          </cylinder>
        </geometry>
        <pose>2.500000 -1.500000 2.000000 0.000000 0.000000 0.000000</pose>
      </collision>
      <visual name="visual10">
        <geometry>
          <cylinder>
            <radius>0.02</radius>
            <length>3.0</length>
          </cylinder>
        </geometry>
        <pose>2.500000 0.000000 0.000000 1.570796 0.000000 0.000000</pose>
        <material>
          <script>
            <uri>file://media/materials/scripts/kitchen.material</uri>
            <name>Gazebo/Black</name>
          </script>
        </material>
      </visual>
      <collision name="collision10">
        <geometry>
          <cylinder>
            <radius>0.02</radius>
          </cylinder>
        </geometry>
        <pose>2.500000 0.000000 0.000000 1.570796 0.000000 0.000000</pose>
      </collision>
      <visual name="visual11">
        <geometry>
          <cylinder>
            <radius>0.02</radius>
            <length>3.0</length>
          </cylinder>
        </geometry>
        <pose>2.500000 0.000000 4.000000 1.570796 0.000000 0.000000</pose>
        <material>
          <script>
            <uri>file://media/materials/scripts/kitchen.material</uri>
            <name>Gazebo/Black</name>
          </script>
        </material>
      </visual>
      <collision name="collision11">
        <geometry>
          <cylinder>
            <radius>0.02</radius>
          </cylinder>
        </geometry>
        <pose>2.500000 0.000000 4.000000 1.570796 0.000000 0.000000</pose>
      </collision>
      <visual name="visual12">
        <geometry>
          <cylinder>
            <radius>0.02</radius>
            <length>4.0</length>
          </cylinder>
        </geometry>
        <pose>2.500000 1.500000 2.000000 0.000000 0.000000 0.000000</pose>
        <material>
          <script>
            <uri>file://media/materials/scripts/kitchen.material</uri>
            <name>Gazebo/Black</name>
          </script>
        </material>
      </visual>
      <collision name="collision12">
        <geometry>
          <cylinder>
            <radius>0.02</radius>
          </cylinder>
        </geometry>
        <pose>2.500000 1.500000 2.000000 0.000000 0.000000 0.000000</pose>
      </collision>
    </link>
    <!--Definition of the robot cables-->
    <!--Definition of the robot platform-->
    <link name="platform">
      <pose>0.000000 0.000000 2.000000 0.000000 0.000000 0.000000</pose>
      <visual name="visualplatform">
        <geometry>
          <box>
            <size>1 0.4 0.2</size>
          </box>
        </geometry>
        <material>
          <script>
            <uri>file://media/materials/scripts/kitchen.material</uri>
            <name>Gazebo/Blue</name>
          </script>
        </material>
      </visual>
      <collision name="collisionplatform">
        <geometry>
          <box>
            <size>1 0.4 0.2</size>
          </box>
        </geometry>
      </collision>
      <inertial>
        <inertia>
          <ixx>5.0</ixx>
          <ixy>0</ixy>
          <ixz>0</ixz>
          <iyy>5.0</iyy>
          <iyz>0</iyz>
          <izz>5.0</izz>
        </inertia>
        <mass>10</mass>
      </inertial>
    </link>
    <link name="cable0">
      <pose>-3.339809 -2.045876 -0.797819 -0.600050 0.715276 -0.230202</pose>
      <visual name="visual">
        <geometry>
          <cylinder>
            <radius>0.005</radius>
            <length>8.66025403784</length>
          </cylinder>
        </geometry>
        <material>
          <script>
            <uri>file://media/materials/scripts/kitchen.material</uri>
            <name>Gazebo/Black</name>
          </script>
        </material>
      </visual>
      <inertial>
        <inertia>
          <ixx>0.0</ixx>
          <ixy>0</ixy>
          <ixz>0</ixz>
          <iyy>0.0</iyy>
          <iyz>0</iyz>
          <izz>0.0</izz>
        </inertia>
        <mass>0.0</mass>
      </inertial>
    </link>
    <link name="virt_X0">
      <inertial>
        <inertia>
          <ixx>0.005</ixx>
          <ixy>0</ixy>
          <ixz>0</ixz>
          <iyy>0.005</iyy>
          <iyz>0</iyz>
          <izz>0.005</izz>
        </inertia>
        <mass>0.01</mass>
      </inertial>
      <pose>-2.500000 -1.500000 0.000000 -0.600050 0.715276 -0.230202</pose>
    </link>
    <joint name="rev_X0" type="revolute">
      <pose>0 0 0 -0.600050 0.715276 -0.230202</pose>
      <parent>frame</parent>
      <child>virt_X0</child>
      <axis>
        <xyz>0.734998 -0.172251 -0.655826</xyz>
        <limit>
          <effort>100</effort>
          <velocity>10</velocity>
        </limit>
        <dynamics>
          <damping>0.01</damping>
        </dynamics>
      </axis>
    </joint>
    <link name="virt_Y0">
      <inertial>
        <inertia>
          <ixx>0.005</ixx>
          <ixy>0</ixy>
          <ixz>0</ixz>
          <iyy>0.005</iyy>
          <iyz>0</iyz>
          <izz>0.005</izz>
        </inertia>
        <mass>0.01</mass>
      </inertial>
      <pose>-2.500000 -1.500000 0.000000 -0.600050 0.715276 -0.230202</pose>
    </link>
    <joint name="rev_Y0" type="revolute">
      <pose>0 0 0 -0.600050 0.715276 -0.230202</pose>
      <parent>virt_Y0</parent>
      <child>virt_X0</child>
      <axis>
        <xyz>-0.172251 0.888037 -0.426287</xyz>
        <limit>
          <effort>100</effort>
          <velocity>10</velocity>
        </limit>
        <dynamics>
          <damping>0.01</damping>
        </dynamics>
      </axis>
    </joint>
    <joint name="linear0" type="prismatic">
      <pose>0 0 1.818240 -0.600050 0.715276 -0.230202</pose>
      <parent>virt_Y0</parent>
      <child>cable0</child>
      <axis>
        <xyz>-0.655826 -0.426287 -0.623035</xyz>
        <limit>
          <lower>-50</lower>
          <upper>50</upper>
          <effort>400</effort>
          <velocity>100</velocity>
        </limit>
        <dynamics>
          <damping>1</damping>
        </dynamics>
      </axis>
    </joint>
    <link name="virt_Xpf0">
      <inertial>
        <inertia>
          <ixx>0.005</ixx>
          <ixy>0</ixy>
          <ixz>0</ixz>
          <iyy>0.005</iyy>
          <iyz>0</iyz>
          <izz>0.005</izz>
        </inertia>
        <mass>0.01</mass>
      </inertial>
      <pose>-0.500000 -0.200000 1.900000 -0.600050 0.715276 -0.230202</pose>
    </link>
    <joint name="rev_Xpf0" type="revolute">
      <pose>0 0 0 -0.600050 0.715276 -0.230202</pose>
      <parent>platform</parent>
      <child>virt_Ypf0</child>
      <axis>
        <xyz>1 0 0</xyz>
        <limit>
          <effort>100</effort>
          <velocity>10</velocity>
        </limit>
        <dynamics>
          <damping>0.01</damping>
        </dynamics>
      </axis>
    </joint>
    <link name="virt_Ypf0">
      <inertial>
        <inertia>
          <ixx>0.005</ixx>
          <ixy>0</ixy>
          <ixz>0</ixz>
          <iyy>0.005</iyy>
          <iyz>0</iyz>
          <izz>0.005</izz>
        </inertia>
        <mass>0.01</mass>
      </inertial>
      <pose>-0.500000 -0.200000 1.900000 -0.600050 0.715276 -0.230202</pose>
    </link>
    <joint name="rev_Ypf0" type="revolute">
      <pose>0 0 0 -0.600050 0.715276 -0.230202</pose>
      <parent>virt_Xpf0</parent>
      <child>virt_Ypf0</child>
      <axis>
        <xyz>0 1 0</xyz>
        <limit>
          <effort>100</effort>
          <velocity>10</velocity>
        </limit>
        <dynamics>
          <damping>0.01</damping>
        </dynamics>
      </axis>
    </joint>
    <joint name="rev_Zpf0" type="revolute">
      <pose>0 0 0 -0.600050 0.715276 -0.230202</pose>
      <child>virt_Ypf0</child>
      <parent>cable0</parent>
      <axis>
        <xyz>0 0 1</xyz>
        <limit>
          <effort>100</effort>
          <velocity>10</velocity>
        </limit>
        <dynamics>
          <damping>0.01</damping>
        </dynamics>
      </axis>
    </joint>
    <plugin filename="libcdpr3.so" name="freefloating_gazebo_control"/>
    <link name="cable1">
      <pose>-3.339809 2.045876 -0.797819 0.600050 0.715276 0.230202</pose>
      <visual name="visual">
        <geometry>
          <cylinder>
            <radius>0.005</radius>
            <length>8.66025403784</length>
          </cylinder>
        </geometry>
        <material>
          <script>
            <uri>file://media/materials/scripts/kitchen.material</uri>
            <name>Gazebo/Black</name>
          </script>
        </material>
      </visual>
      <inertial>
        <inertia>
          <ixx>0.0</ixx>
          <ixy>0</ixy>
          <ixz>0</ixz>
          <iyy>0.0</iyy>
          <iyz>0</iyz>
          <izz>0.0</izz>
        </inertia>
        <mass>0.0</mass>
      </inertial>
    </link>
    <link name="virt_X1">
      <inertial>
        <inertia>
          <ixx>0.005</ixx>
          <ixy>0</ixy>
          <ixz>0</ixz>
          <iyy>0.005</iyy>
          <iyz>0</iyz>
          <izz>0.005</izz>
        </inertia>
        <mass>0.01</mass>
      </inertial>
      <pose>-2.500000 1.500000 0.000000 0.600050 0.715276 0.230202</pose>
    </link>
    <joint name="rev_X1" type="revolute">
      <pose>0 0 0 0.600050 0.715276 0.230202</pose>
      <parent>frame</parent>
      <child>virt_X1</child>
      <axis>
        <xyz>0.734998 0.172251 -0.655826</xyz>
        <limit>
          <effort>100</effort>
          <velocity>10</velocity>
        </limit>
        <dynamics>
          <damping>0.01</damping>
        </dynamics>
      </axis>
    </joint>
    <link name="virt_Y1">
      <inertial>
        <inertia>
          <ixx>0.005</ixx>
          <ixy>0</ixy>
          <ixz>0</ixz>
          <iyy>0.005</iyy>
          <iyz>0</iyz>
          <izz>0.005</izz>
        </inertia>
        <mass>0.01</mass>
      </inertial>
      <pose>-2.500000 1.500000 0.000000 0.600050 0.715276 0.230202</pose>
    </link>
    <joint name="rev_Y1" type="revolute">
      <pose>0 0 0 0.600050 0.715276 0.230202</pose>
      <parent>virt_Y1</parent>
      <child>virt_X1</child>
      <axis>
        <xyz>0.172251 0.888037 0.426287</xyz>
        <limit>
          <effort>100</effort>
          <velocity>10</velocity>
        </limit>
        <dynamics>
          <damping>0.01</damping>
        </dynamics>
      </axis>
    </joint>
    <joint name="linear1" type="prismatic">
      <pose>0 0 1.818240 0.600050 0.715276 0.230202</pose>
      <parent>virt_Y1</parent>
      <child>cable1</child>
      <axis>
        <xyz>-0.655826 0.426287 -0.623035</xyz>
        <limit>
          <lower>-50</lower>
          <upper>50</upper>
          <effort>400</effort>
          <velocity>100</velocity>
        </limit>
        <dynamics>
          <damping>1</damping>
        </dynamics>
      </axis>
    </joint>
    <link name="virt_Xpf1">
      <inertial>
        <inertia>
          <ixx>0.005</ixx>
          <ixy>0</ixy>
          <ixz>0</ixz>
          <iyy>0.005</iyy>
          <iyz>0</iyz>
          <izz>0.005</izz>
        </inertia>
        <mass>0.01</mass>
      </inertial>
      <pose>-0.500000 0.200000 1.900000 0.600050 0.715276 0.230202</pose>
    </link>
    <joint name="rev_Xpf1" type="revolute">
      <pose>0 0 0 0.600050 0.715276 0.230202</pose>
      <parent>platform</parent>
      <child>virt_Ypf1</child>
      <axis>
        <xyz>1 0 0</xyz>
        <limit>
          <effort>100</effort>
          <velocity>10</velocity>
        </limit>
        <dynamics>
          <damping>0.01</damping>
        </dynamics>
      </axis>
    </joint>
    <link name="virt_Ypf1">
      <inertial>
        <inertia>
          <ixx>0.005</ixx>
          <ixy>0</ixy>
          <ixz>0</ixz>
          <iyy>0.005</iyy>
          <iyz>0</iyz>
          <izz>0.005</izz>
        </inertia>
        <mass>0.01</mass>
      </inertial>
      <pose>-0.500000 0.200000 1.900000 0.600050 0.715276 0.230202</pose>
    </link>
    <joint name="rev_Ypf1" type="revolute">
      <pose>0 0 0 0.600050 0.715276 0.230202</pose>
      <parent>virt_Xpf1</parent>
      <child>virt_Ypf1</child>
      <axis>
        <xyz>0 1 0</xyz>
        <limit>
          <effort>100</effort>
          <velocity>10</velocity>
        </limit>
        <dynamics>
          <damping>0.01</damping>
        </dynamics>
      </axis>
    </joint>
    <joint name="rev_Zpf1" type="revolute">
      <pose>0 0 0 0.600050 0.715276 0.230202</pose>
      <child>virt_Ypf1</child>
      <parent>cable1</parent>
      <axis>
        <xyz>0 0 1</xyz>
        <limit>
          <effort>100</effort>
          <velocity>10</velocity>
        </limit>
        <dynamics>
          <damping>0.01</damping>
        </dynamics>
      </axis>
    </joint>
    <plugin filename="libcdpr3.so" name="freefloating_gazebo_control"/>
    <link name="cable2">
      <pose>3.339809 2.045876 -0.797819 0.600050 -0.715276 -0.230202</pose>
      <visual name="visual">
        <geometry>
          <cylinder>
            <radius>0.005</radius>
            <length>8.66025403784</length>
          </cylinder>
        </geometry>
        <material>
          <script>
            <uri>file://media/materials/scripts/kitchen.material</uri>
            <name>Gazebo/Black</name>
          </script>
        </material>
      </visual>
      <inertial>
        <inertia>
          <ixx>0.0</ixx>
          <ixy>0</ixy>
          <ixz>0</ixz>
          <iyy>0.0</iyy>
          <iyz>0</iyz>
          <izz>0.0</izz>
        </inertia>
        <mass>0.0</mass>
      </inertial>
    </link>
    <link name="virt_X2">
      <inertial>
        <inertia>
          <ixx>0.005</ixx>
          <ixy>0</ixy>
          <ixz>0</ixz>
          <iyy>0.005</iyy>
          <iyz>0</iyz>
          <izz>0.005</izz>
        </inertia>
        <mass>0.01</mass>
      </inertial>
      <pose>2.500000 1.500000 0.000000 0.600050 -0.715276 -0.230202</pose>
    </link>
    <joint name="rev_X2" type="revolute">
      <pose>0 0 0 0.600050 -0.715276 -0.230202</pose>
      <parent>frame</parent>
      <child>virt_X2</child>
      <axis>
        <xyz>0.734998 -0.172251 0.655826</xyz>
        <limit>
          <effort>100</effort>
          <velocity>10</velocity>
        </limit>
        <dynamics>
          <damping>0.01</damping>
        </dynamics>
      </axis>
    </joint>
    <link name="virt_Y2">
      <inertial>
        <inertia>
          <ixx>0.005</ixx>
          <ixy>0</ixy>
          <ixz>0</ixz>
          <iyy>0.005</iyy>
          <iyz>0</iyz>
          <izz>0.005</izz>
        </inertia>
        <mass>0.01</mass>
      </inertial>
      <pose>2.500000 1.500000 0.000000 0.600050 -0.715276 -0.230202</pose>
    </link>
    <joint name="rev_Y2" type="revolute">
      <pose>0 0 0 0.600050 -0.715276 -0.230202</pose>
      <parent>virt_Y2</parent>
      <child>virt_X2</child>
      <axis>
        <xyz>-0.172251 0.888037 0.426287</xyz>
        <limit>
          <effort>100</effort>
          <velocity>10</velocity>
        </limit>
        <dynamics>
          <damping>0.01</damping>
        </dynamics>
      </axis>
    </joint>
    <joint name="linear2" type="prismatic">
      <pose>0 0 1.818240 0.600050 -0.715276 -0.230202</pose>
      <parent>virt_Y2</parent>
      <child>cable2</child>
      <axis>
        <xyz>0.655826 0.426287 -0.623035</xyz>
        <limit>
          <lower>-50</lower>
          <upper>50</upper>
          <effort>400</effort>
          <velocity>100</velocity>
        </limit>
        <dynamics>
          <damping>1</damping>
        </dynamics>
      </axis>
    </joint>
    <link name="virt_Xpf2">
      <inertial>
        <inertia>
          <ixx>0.005</ixx>
          <ixy>0</ixy>
          <ixz>0</ixz>
          <iyy>0.005</iyy>
          <iyz>0</iyz>
          <izz>0.005</izz>
        </inertia>
        <mass>0.01</mass>
      </inertial>
      <pose>0.500000 0.200000 1.900000 0.600050 -0.715276 -0.230202</pose>
    </link>
    <joint name="rev_Xpf2" type="revolute">
      <pose>0 0 0 0.600050 -0.715276 -0.230202</pose>
      <parent>platform</parent>
      <child>virt_Ypf2</child>
      <axis>
        <xyz>1 0 0</xyz>
        <limit>
          <effort>100</effort>
          <velocity>10</velocity>
        </limit>
        <dynamics>
          <damping>0.01</damping>
        </dynamics>
      </axis>
    </joint>
    <link name="virt_Ypf2">
      <inertial>
        <inertia>
          <ixx>0.005</ixx>
          <ixy>0</ixy>
          <ixz>0</ixz>
          <iyy>0.005</iyy>
          <iyz>0</iyz>
          <izz>0.005</izz>
        </inertia>
        <mass>0.01</mass>
      </inertial>
      <pose>0.500000 0.200000 1.900000 0.600050 -0.715276 -0.230202</pose>
    </link>
    <joint name="rev_Ypf2" type="revolute">
      <pose>0 0 0 0.600050 -0.715276 -0.230202</pose>
      <parent>virt_Xpf2</parent>
      <child>virt_Ypf2</child>
      <axis>
        <xyz>0 1 0</xyz>
        <limit>
          <effort>100</effort>
          <velocity>10</velocity>
        </limit>
        <dynamics>
          <damping>0.01</damping>
        </dynamics>
      </axis>
    </joint>
    <joint name="rev_Zpf2" type="revolute">
      <pose>0 0 0 0.600050 -0.715276 -0.230202</pose>
      <child>virt_Ypf2</child>
      <parent>cable2</parent>
      <axis>
        <xyz>0 0 1</xyz>
        <limit>
          <effort>100</effort>
          <velocity>10</velocity>
        </limit>
        <dynamics>
          <damping>0.01</damping>
        </dynamics>
      </axis>
    </joint>
    <plugin filename="libcdpr3.so" name="freefloating_gazebo_control"/>
    <link name="cable3">
      <pose>3.339809 -2.045876 -0.797819 -0.600050 -0.715276 0.230202</pose>
      <visual name="visual">
        <geometry>
          <cylinder>
            <radius>0.005</radius>
            <length>8.66025403784</length>
          </cylinder>
        </geometry>
        <material>
          <script>
            <uri>file://media/materials/scripts/kitchen.material</uri>
            <name>Gazebo/Black</name>
          </script>
        </material>
      </visual>
      <inertial>
        <inertia>
          <ixx>0.0</ixx>
          <ixy>0</ixy>
          <ixz>0</ixz>
          <iyy>0.0</iyy>
          <iyz>0</iyz>
          <izz>0.0</izz>
        </inertia>
        <mass>0.0</mass>
      </inertial>
    </link>
    <link name="virt_X3">
      <inertial>
        <inertia>
          <ixx>0.005</ixx>
          <ixy>0</ixy>
          <ixz>0</ixz>
          <iyy>0.005</iyy>
          <iyz>0</iyz>
          <izz>0.005</izz>
        </inertia>
        <mass>0.01</mass>
      </inertial>
      <pose>2.500000 -1.500000 0.000000 -0.600050 -0.715276 0.230202</pose>
    </link>
    <joint name="rev_X3" type="revolute">
      <pose>0 0 0 -0.600050 -0.715276 0.230202</pose>
      <parent>frame</parent>
      <child>virt_X3</child>
      <axis>
        <xyz>0.734998 0.172251 0.655826</xyz>
        <limit>
          <effort>100</effort>
          <velocity>10</velocity>
        </limit>
        <dynamics>
          <damping>0.01</damping>
        </dynamics>
      </axis>
    </joint>
    <link name="virt_Y3">
      <inertial>
        <inertia>
          <ixx>0.005</ixx>
          <ixy>0</ixy>
          <ixz>0</ixz>
          <iyy>0.005</iyy>
          <iyz>0</iyz>
          <izz>0.005</izz>
        </inertia>
        <mass>0.01</mass>
      </inertial>
      <pose>2.500000 -1.500000 0.000000 -0.600050 -0.715276 0.230202</pose>
    </link>
    <joint name="rev_Y3" type="revolute">
      <pose>0 0 0 -0.600050 -0.715276 0.230202</pose>
      <parent>virt_Y3</parent>
      <child>virt_X3</child>
      <axis>
        <xyz>0.172251 0.888037 -0.426287</xyz>
        <limit>
          <effort>100</effort>
          <velocity>10</velocity>
        </limit>
        <dynamics>
          <damping>0.01</damping>
        </dynamics>
      </axis>
    </joint>
    <joint name="linear3" type="prismatic">
      <pose>0 0 1.818240 -0.600050 -0.715276 0.230202</pose>
      <parent>virt_Y3</parent>
      <child>cable3</child>
      <axis>
        <xyz>0.655826 -0.426287 -0.623035</xyz>
        <limit>
          <lower>-50</lower>
          <upper>50</upper>
          <effort>400</effort>
          <velocity>100</velocity>
        </limit>
        <dynamics>
          <damping>1</damping>
        </dynamics>
      </axis>
    </joint>
    <link name="virt_Xpf3">
      <inertial>
        <inertia>
          <ixx>0.005</ixx>
          <ixy>0</ixy>
          <ixz>0</ixz>
          <iyy>0.005</iyy>
          <iyz>0</iyz>
          <izz>0.005</izz>
        </inertia>
        <mass>0.01</mass>
      </inertial>
      <pose>0.500000 -0.200000 1.900000 -0.600050 -0.715276 0.230202</pose>
    </link>
    <joint name="rev_Xpf3" type="revolute">
      <pose>0 0 0 -0.600050 -0.715276 0.230202</pose>
      <parent>platform</parent>
      <child>virt_Ypf3</child>
      <axis>
        <xyz>1 0 0</xyz>
        <limit>
          <effort>100</effort>
          <velocity>10</velocity>
        </limit>
        <dynamics>
          <damping>0.01</damping>
        </dynamics>
      </axis>
    </joint>
    <link name="virt_Ypf3">
      <inertial>
        <inertia>
          <ixx>0.005</ixx>
          <ixy>0</ixy>
          <ixz>0</ixz>
          <iyy>0.005</iyy>
          <iyz>0</iyz>
          <izz>0.005</izz>
        </inertia>
        <mass>0.01</mass>
      </inertial>
      <pose>0.500000 -0.200000 1.900000 -0.600050 -0.715276 0.230202</pose>
    </link>
    <joint name="rev_Ypf3" type="revolute">
      <pose>0 0 0 -0.600050 -0.715276 0.230202</pose>
      <parent>virt_Xpf3</parent>
      <child>virt_Ypf3</child>
      <axis>
        <xyz>0 1 0</xyz>
        <limit>
          <effort>100</effort>
          <velocity>10</velocity>
        </limit>
        <dynamics>
          <damping>0.01</damping>
        </dynamics>
      </axis>
    </joint>
    <joint name="rev_Zpf3" type="revolute">
      <pose>0 0 0 -0.600050 -0.715276 0.230202</pose>
      <child>virt_Ypf3</child>
      <parent>cable3</parent>
      <axis>
        <xyz>0 0 1</xyz>
        <limit>
          <effort>100</effort>
          <velocity>10</velocity>
        </limit>
        <dynamics>
          <damping>0.01</damping>
        </dynamics>
      </axis>
    </joint>
    <plugin filename="libcdpr3.so" name="freefloating_gazebo_control"/>
    <link name="cable4">
      <pose>-3.339809 -2.045876 4.797819 -2.541542 0.715276 -1.758640</pose>
      <visual name="visual">
        <geometry>
          <cylinder>
            <radius>0.005</radius>
            <length>8.66025403784</length>
          </cylinder>
        </geometry>
        <material>
          <script>
            <uri>file://media/materials/scripts/kitchen.material</uri>
            <name>Gazebo/Black</name>
          </script>
        </material>
      </visual>
      <inertial>
        <inertia>
          <ixx>0.0</ixx>
          <ixy>0</ixy>
          <ixz>0</ixz>
          <iyy>0.0</iyy>
          <iyz>0</iyz>
          <izz>0.0</izz>
        </inertia>
        <mass>0.0</mass>
      </inertial>
    </link>
    <link name="virt_X4">
      <inertial>
        <inertia>
          <ixx>0.005</ixx>
          <ixy>0</ixy>
          <ixz>0</ixz>
          <iyy>0.005</iyy>
          <iyz>0</iyz>
          <izz>0.005</izz>
        </inertia>
        <mass>0.01</mass>
      </inertial>
      <pose>-2.500000 -1.500000 4.000000 -2.541542 0.715276 -1.758640</pose>
    </link>
    <joint name="rev_X4" type="revolute">
      <pose>0 0 0 -2.541542 0.715276 -1.758640</pose>
      <parent>frame</parent>
      <child>virt_X4</child>
      <axis>
        <xyz>-0.140973 -0.741633 -0.655826</xyz>
        <limit>
          <effort>100</effort>
          <velocity>10</velocity>
        </limit>
        <dynamics>
          <damping>0.01</damping>
        </dynamics>
      </axis>
    </joint>
    <link name="virt_Y4">
      <inertial>
        <inertia>
          <ixx>0.005</ixx>
          <ixy>0</ixy>
          <ixz>0</ixz>
          <iyy>0.005</iyy>
          <iyz>0</iyz>
          <izz>0.005</izz>
        </inertia>
        <mass>0.01</mass>
      </inertial>
      <pose>-2.500000 -1.500000 4.000000 -2.541542 0.715276 -1.758640</pose>
    </link>
    <joint name="rev_Y4" type="revolute">
      <pose>0 0 0 -2.541542 0.715276 -1.758640</pose>
      <parent>virt_Y4</parent>
      <child>virt_X4</child>
      <axis>
        <xyz>-0.741633 0.517939 -0.426287</xyz>
        <limit>
          <effort>100</effort>
          <velocity>10</velocity>
        </limit>
        <dynamics>
          <damping>0.01</damping>
        </dynamics>
      </axis>
    </joint>
    <joint name="linear4" type="prismatic">
      <pose>0 0 1.818240 -2.541542 0.715276 -1.758640</pose>
      <parent>virt_Y4</parent>
      <child>cable4</child>
      <axis>
        <xyz>-0.655826 -0.426287 0.623035</xyz>
        <limit>
          <lower>-50</lower>
          <upper>50</upper>
          <effort>400</effort>
          <velocity>100</velocity>
        </limit>
        <dynamics>
          <damping>1</damping>
        </dynamics>
      </axis>
    </joint>
    <link name="virt_Xpf4">
      <inertial>
        <inertia>
          <ixx>0.005</ixx>
          <ixy>0</ixy>
          <ixz>0</ixz>
          <iyy>0.005</iyy>
          <iyz>0</iyz>
          <izz>0.005</izz>
        </inertia>
        <mass>0.01</mass>
      </inertial>
      <pose>-0.500000 -0.200000 2.100000 -2.541542 0.715276 -1.758640</pose>
    </link>
    <joint name="rev_Xpf4" type="revolute">
      <pose>0 0 0 -2.541542 0.715276 -1.758640</pose>
      <parent>platform</parent>
      <child>virt_Ypf4</child>
      <axis>
        <xyz>1 0 0</xyz>
        <limit>
          <effort>100</effort>
          <velocity>10</velocity>
        </limit>
        <dynamics>
          <damping>0.01</damping>
        </dynamics>
      </axis>
    </joint>
    <link name="virt_Ypf4">
      <inertial>
        <inertia>
          <ixx>0.005</ixx>
          <ixy>0</ixy>
          <ixz>0</ixz>
          <iyy>0.005</iyy>
          <iyz>0</iyz>
          <izz>0.005</izz>
        </inertia>
        <mass>0.01</mass>
      </inertial>
      <pose>-0.500000 -0.200000 2.100000 -2.541542 0.715276 -1.758640</pose>
    </link>
    <joint name="rev_Ypf4" type="revolute">
      <pose>0 0 0 -2.541542 0.715276 -1.758640</pose>
      <parent>virt_Xpf4</parent>
      <child>virt_Ypf4</child>
      <axis>
        <xyz>0 1 0</xyz>
        <limit>
          <effort>100</effort>
          <velocity>10</velocity>
        </limit>
        <dynamics>
          <damping>0.01</damping>
        </dynamics>
      </axis>
    </joint>
    <joint name="rev_Zpf4" type="revolute">
      <pose>0 0 0 -2.541542 0.715276 -1.758640</pose>
      <child>virt_Ypf4</child>
      <parent>cable4</parent>
      <axis>
        <xyz>0 0 1</xyz>
        <limit>
          <effort>100</effort>
          <velocity>10</velocity>
        </limit>
        <dynamics>
          <damping>0.01</damping>
        </dynamics>
      </axis>
    </joint>
    <plugin filename="libcdpr3.so" name="freefloating_gazebo_control"/>
    <link name="cable5">
      <pose>-3.339809 2.045876 4.797819 2.541542 0.715276 1.758640</pose>
      <visual name="visual">
        <geometry>
          <cylinder>
            <radius>0.005</radius>
            <length>8.66025403784</length>
          </cylinder>
        </geometry>
        <material>
          <script>
            <uri>file://media/materials/scripts/kitchen.material</uri>
            <name>Gazebo/Black</name>
          </script>
        </material>
      </visual>
      <inertial>
        <inertia>
          <ixx>0.0</ixx>
          <ixy>0</ixy>
          <ixz>0</ixz>
          <iyy>0.0</iyy>
          <iyz>0</iyz>
          <izz>0.0</izz>
        </inertia>
        <mass>0.0</mass>
      </inertial>
    </link>
    <link name="virt_X5">
      <inertial>
        <inertia>
          <ixx>0.005</ixx>
          <ixy>0</ixy>
          <ixz>0</ixz>
          <iyy>0.005</iyy>
          <iyz>0</iyz>
          <izz>0.005</izz>
        </inertia>
        <mass>0.01</mass>
      </inertial>
      <pose>-2.500000 1.500000 4.000000 2.541542 0.715276 1.758640</pose>
    </link>
    <joint name="rev_X5" type="revolute">
      <pose>0 0 0 2.541542 0.715276 1.758640</pose>
      <parent>frame</parent>
      <child>virt_X5</child>
      <axis>
        <xyz>-0.140973 0.741633 -0.655826</xyz>
        <limit>
          <effort>100</effort>
          <velocity>10</velocity>
        </limit>
        <dynamics>
          <damping>0.01</damping>
        </dynamics>
      </axis>
    </joint>
    <link name="virt_Y5">
      <inertial>
        <inertia>
          <ixx>0.005</ixx>
          <ixy>0</ixy>
          <ixz>0</ixz>
          <iyy>0.005</iyy>
          <iyz>0</iyz>
          <izz>0.005</izz>
        </inertia>
        <mass>0.01</mass>
      </inertial>
      <pose>-2.500000 1.500000 4.000000 2.541542 0.715276 1.758640</pose>
    </link>
    <joint name="rev_Y5" type="revolute">
      <pose>0 0 0 2.541542 0.715276 1.758640</pose>
      <parent>virt_Y5</parent>
      <child>virt_X5</child>
      <axis>
        <xyz>0.741633 0.517939 0.426287</xyz>
        <limit>
          <effort>100</effort>
          <velocity>10</velocity>
        </limit>
        <dynamics>
          <damping>0.01</damping>
        </dynamics>
      </axis>
    </joint>
    <joint name="linear5" type="prismatic">
      <pose>0 0 1.818240 2.541542 0.715276 1.758640</pose>
      <parent>virt_Y5</parent>
      <child>cable5</child>
      <axis>
        <xyz>-0.655826 0.426287 0.623035</xyz>
        <limit>
          <lower>-50</lower>
          <upper>50</upper>
          <effort>400</effort>
          <velocity>100</velocity>
        </limit>
        <dynamics>
          <damping>1</damping>
        </dynamics>
      </axis>
    </joint>
    <link name="virt_Xpf5">
      <inertial>
        <inertia>
          <ixx>0.005</ixx>
          <ixy>0</ixy>
          <ixz>0</ixz>
          <iyy>0.005</iyy>
          <iyz>0</iyz>
          <izz>0.005</izz>
        </inertia>
        <mass>0.01</mass>
      </inertial>
      <pose>-0.500000 0.200000 2.100000 2.541542 0.715276 1.758640</pose>
    </link>
    <joint name="rev_Xpf5" type="revolute">
      <pose>0 0 0 2.541542 0.715276 1.758640</pose>
      <parent>platform</parent>
      <child>virt_Ypf5</child>
      <axis>
        <xyz>1 0 0</xyz>
        <limit>
          <effort>100</effort>
          <velocity>10</velocity>
        </limit>
        <dynamics>
          <damping>0.01</damping>
        </dynamics>
      </axis>
    </joint>
    <link name="virt_Ypf5">
      <inertial>
        <inertia>
          <ixx>0.005</ixx>
          <ixy>0</ixy>
          <ixz>0</ixz>
          <iyy>0.005</iyy>
          <iyz>0</iyz>
          <izz>0.005</izz>
        </inertia>
        <mass>0.01</mass>
      </inertial>
      <pose>-0.500000 0.200000 2.100000 2.541542 0.715276 1.758640</pose>
    </link>
    <joint name="rev_Ypf5" type="revolute">
      <pose>0 0 0 2.541542 0.715276 1.758640</pose>
      <parent>virt_Xpf5</parent>
      <child>virt_Ypf5</child>
      <axis>
        <xyz>0 1 0</xyz>
        <limit>
          <effort>100</effort>
          <velocity>10</velocity>
        </limit>
        <dynamics>
          <damping>0.01</damping>
        </dynamics>
      </axis>
    </joint>
    <joint name="rev_Zpf5" type="revolute">
      <pose>0 0 0 2.541542 0.715276 1.758640</pose>
      <child>virt_Ypf5</child>
      <parent>cable5</parent>
      <axis>
        <xyz>0 0 1</xyz>
        <limit>
          <effort>100</effort>
          <velocity>10</velocity>
        </limit>
        <dynamics>
          <damping>0.01</damping>
        </dynamics>
      </axis>
    </joint>
    <plugin filename="libcdpr3.so" name="freefloating_gazebo_control"/>
    <link name="cable6">
      <pose>3.339809 2.045876 4.797819 2.541542 -0.715276 -1.758640</pose>
      <visual name="visual">
        <geometry>
          <cylinder>
            <radius>0.005</radius>
            <length>8.66025403784</length>
          </cylinder>
        </geometry>
        <material>
          <script>
            <uri>file://media/materials/scripts/kitchen.material</uri>
            <name>Gazebo/Black</name>
          </script>
        </material>
      </visual>
      <inertial>
        <inertia>
          <ixx>0.0</ixx>
          <ixy>0</ixy>
          <ixz>0</ixz>
          <iyy>0.0</iyy>
          <iyz>0</iyz>
          <izz>0.0</izz>
        </inertia>
        <mass>0.0</mass>
      </inertial>
    </link>
    <link name="virt_X6">
      <inertial>
        <inertia>
          <ixx>0.005</ixx>
          <ixy>0</ixy>
          <ixz>0</ixz>
          <iyy>0.005</iyy>
          <iyz>0</iyz>
          <izz>0.005</izz>
        </inertia>
        <mass>0.01</mass>
      </inertial>
      <pose>2.500000 1.500000 4.000000 2.541542 -0.715276 -1.758640</pose>
    </link>
    <joint name="rev_X6" type="revolute">
      <pose>0 0 0 2.541542 -0.715276 -1.758640</pose>
      <parent>frame</parent>
      <child>virt_X6</child>
      <axis>
        <xyz>-0.140973 -0.741633 0.655826</xyz>
        <limit>
          <effort>100</effort>
          <velocity>10</velocity>
        </limit>
        <dynamics>
          <damping>0.01</damping>
        </dynamics>
      </axis>
    </joint>
    <link name="virt_Y6">
      <inertial>
        <inertia>
          <ixx>0.005</ixx>
          <ixy>0</ixy>
          <ixz>0</ixz>
          <iyy>0.005</iyy>
          <iyz>0</iyz>
          <izz>0.005</izz>
        </inertia>
        <mass>0.01</mass>
      </inertial>
      <pose>2.500000 1.500000 4.000000 2.541542 -0.715276 -1.758640</pose>
    </link>
    <joint name="rev_Y6" type="revolute">
      <pose>0 0 0 2.541542 -0.715276 -1.758640</pose>
      <parent>virt_Y6</parent>
      <child>virt_X6</child>
      <axis>
        <xyz>-0.741633 0.517939 0.426287</xyz>
        <limit>
          <effort>100</effort>
          <velocity>10</velocity>
        </limit>
        <dynamics>
          <damping>0.01</damping>
        </dynamics>
      </axis>
    </joint>
    <joint name="linear6" type="prismatic">
      <pose>0 0 1.818240 2.541542 -0.715276 -1.758640</pose>
      <parent>virt_Y6</parent>
      <child>cable6</child>
      <axis>
        <xyz>0.655826 0.426287 0.623035</xyz>
        <limit>
          <lower>-50</lower>
          <upper>50</upper>
          <effort>400</effort>
          <velocity>100</velocity>
        </limit>
        <dynamics>
          <damping>1</damping>
        </dynamics>
      </axis>
    </joint>
    <link name="virt_Xpf6">
      <inertial>
        <inertia>
          <ixx>0.005</ixx>
          <ixy>0</ixy>
          <ixz>0</ixz>
          <iyy>0.005</iyy>
          <iyz>0</iyz>
          <izz>0.005</izz>
        </inertia>
        <mass>0.01</mass>
      </inertial>
      <pose>0.500000 0.200000 2.100000 2.541542 -0.715276 -1.758640</pose>
    </link>
    <joint name="rev_Xpf6" type="revolute">
      <pose>0 0 0 2.541542 -0.715276 -1.758640</pose>
      <parent>platform</parent>
      <child>virt_Ypf6</child>
      <axis>
        <xyz>1 0 0</xyz>
        <limit>
          <effort>100</effort>
          <velocity>10</velocity>
        </limit>
        <dynamics>
          <damping>0.01</damping>
        </dynamics>
      </axis>
    </joint>
    <link name="virt_Ypf6">
      <inertial>
        <inertia>
          <ixx>0.005</ixx>
          <ixy>0</ixy>
          <ixz>0</ixz>
          <iyy>0.005</iyy>
          <iyz>0</iyz>
          <izz>0.005</izz>
        </inertia>
        <mass>0.01</mass>
      </inertial>
      <pose>0.500000 0.200000 2.100000 2.541542 -0.715276 -1.758640</pose>
    </link>
    <joint name="rev_Ypf6" type="revolute">
      <pose>0 0 0 2.541542 -0.715276 -1.758640</pose>
      <parent>virt_Xpf6</parent>
      <child>virt_Ypf6</child>
      <axis>
        <xyz>0 1 0</xyz>
        <limit>
          <effort>100</effort>
          <velocity>10</velocity>
        </limit>
        <dynamics>
          <damping>0.01</damping>
        </dynamics>
      </axis>
    </joint>
    <joint name="rev_Zpf6" type="revolute">
      <pose>0 0 0 2.541542 -0.715276 -1.758640</pose>
      <child>virt_Ypf6</child>
      <parent>cable6</parent>
      <axis>
        <xyz>0 0 1</xyz>
        <limit>
          <effort>100</effort>
          <velocity>10</velocity>
        </limit>
        <dynamics>
          <damping>0.01</damping>
        </dynamics>
      </axis>
    </joint>
    <plugin filename="libcdpr3.so" name="freefloating_gazebo_control"/>
    <link name="cable7">
      <pose>3.339809 -2.045876 4.797819 -2.541542 -0.715276 1.758640</pose>
      <visual name="visual">
        <geometry>
          <cylinder>
            <radius>0.005</radius>
            <length>8.66025403784</length>
          </cylinder>
        </geometry>
        <material>
          <script>
            <uri>file://media/materials/scripts/kitchen.material</uri>
            <name>Gazebo/Black</name>
          </script>
        </material>
      </visual>
      <inertial>
        <inertia>
          <ixx>0.0</ixx>
          <ixy>0</ixy>
          <ixz>0</ixz>
          <iyy>0.0</iyy>
          <iyz>0</iyz>
          <izz>0.0</izz>
        </inertia>
        <mass>0.0</mass>
      </inertial>
    </link>
    <link name="virt_X7">
      <inertial>
        <inertia>
          <ixx>0.005</ixx>
          <ixy>0</ixy>
          <ixz>0</ixz>
          <iyy>0.005</iyy>
          <iyz>0</iyz>
          <izz>0.005</izz>
        </inertia>
        <mass>0.01</mass>
      </inertial>
      <pose>2.500000 -1.500000 4.000000 -2.541542 -0.715276 1.758640</pose>
    </link>
    <joint name="rev_X7" type="revolute">
      <pose>0 0 0 -2.541542 -0.715276 1.758640</pose>
      <parent>frame</parent>
      <child>virt_X7</child>
      <axis>
        <xyz>-0.140973 0.741633 0.655826</xyz>
        <limit>
          <effort>100</effort>
          <velocity>10</velocity>
        </limit>
        <dynamics>
          <damping>0.01</damping>
        </dynamics>
      </axis>
    </joint>
    <link name="virt_Y7">
      <inertial>
        <inertia>
          <ixx>0.005</ixx>
          <ixy>0</ixy>
          <ixz>0</ixz>
          <iyy>0.005</iyy>
          <iyz>0</iyz>
          <izz>0.005</izz>
        </inertia>
        <mass>0.01</mass>
      </inertial>
      <pose>2.500000 -1.500000 4.000000 -2.541542 -0.715276 1.758640</pose>
    </link>
    <joint name="rev_Y7" type="revolute">
      <pose>0 0 0 -2.541542 -0.715276 1.758640</pose>
      <parent>virt_Y7</parent>
      <child>virt_X7</child>
      <axis>
        <xyz>0.741633 0.517939 -0.426287</xyz>
        <limit>
          <effort>100</effort>
          <velocity>10</velocity>
        </limit>
        <dynamics>
          <damping>0.01</damping>
        </dynamics>
      </axis>
    </joint>
    <joint name="linear7" type="prismatic">
      <pose>0 0 1.818240 -2.541542 -0.715276 1.758640</pose>
      <parent>virt_Y7</parent>
      <child>cable7</child>
      <axis>
        <xyz>0.655826 -0.426287 0.623035</xyz>
        <limit>
          <lower>-50</lower>
          <upper>50</upper>
          <effort>400</effort>
          <velocity>100</velocity>
        </limit>
        <dynamics>
          <damping>1</damping>
        </dynamics>
      </axis>
    </joint>
    <link name="virt_Xpf7">
      <inertial>
        <inertia>
          <ixx>0.005</ixx>
          <ixy>0</ixy>
          <ixz>0</ixz>
          <iyy>0.005</iyy>
          <iyz>0</iyz>
          <izz>0.005</izz>
        </inertia>
        <mass>0.01</mass>
      </inertial>
      <pose>0.500000 -0.200000 2.100000 -2.541542 -0.715276 1.758640</pose>
    </link>
    <joint name="rev_Xpf7" type="revolute">
      <pose>0 0 0 -2.541542 -0.715276 1.758640</pose>
      <parent>platform</parent>
      <child>virt_Ypf7</child>
      <axis>
        <xyz>1 0 0</xyz>
        <limit>
          <effort>100</effort>
          <velocity>10</velocity>
        </limit>
        <dynamics>
          <damping>0.01</damping>
        </dynamics>
      </axis>
    </joint>
    <link name="virt_Ypf7">
      <inertial>
        <inertia>
          <ixx>0.005</ixx>
          <ixy>0</ixy>
          <ixz>0</ixz>
          <iyy>0.005</iyy>
          <iyz>0</iyz>
          <izz>0.005</izz>
        </inertia>
        <mass>0.01</mass>
      </inertial>
      <pose>0.500000 -0.200000 2.100000 -2.541542 -0.715276 1.758640</pose>
    </link>
    <joint name="rev_Ypf7" type="revolute">
      <pose>0 0 0 -2.541542 -0.715276 1.758640</pose>
      <parent>virt_Xpf7</parent>
      <child>virt_Ypf7</child>
      <axis>
        <xyz>0 1 0</xyz>
        <limit>
          <effort>100</effort>
          <velocity>10</velocity>
        </limit>
        <dynamics>
          <damping>0.01</damping>
        </dynamics>
      </axis>
    </joint>
    <joint name="rev_Zpf7" type="revolute">
      <pose>0 0 0 -2.541542 -0.715276 1.758640</pose>
      <child>virt_Ypf7</child>
      <parent>cable7</parent>
      <axis>
        <xyz>0 0 1</xyz>
        <limit>
          <effort>100</effort>
          <velocity>10</velocity>
        </limit>
        <dynamics>
          <damping>0.01</damping>
        </dynamics>
      </axis>
    </joint>
    <plugin filename="libcdpr3.so" name="freefloating_gazebo_control"/>
  </model>
</sdf>
